Workbook

Sheet Petunjuk
A1: FORMAT PENGOLAHAN DATA PRA-TINDAKAN PTK
A2: Peningkatan Kemampuan Berpikir Algoritmik melalui Problem Based Learning
A4: Satuan Pendidikan | B4: SMAN 15 Bandung | D4: Petunjuk Penggunaan
A5: Kelas / Fase | B5: X-5 / Fase E | D5: 1. | E5: Masukkan skor 1–4 untuk enam indikator pada sheet Data Diagnostik.
A6: Jumlah Peserta Didik | B6: 46 | D6: 2. | E6: Nilai, total skor, dan ketuntasan akan dihitung otomatis.
A7: KKTP | B7: 75 | D7: 3. | E7: Masukkan skor observasi K1–K5 pada sheet Observasi Kemandirian.
A8: Alokasi Waktu | B8: 2 JP (2 × 40 menit) | D8: 4. | E8: Rekap kelas, capaian indikator, dan grafik tersedia otomatis pada sheet Rekap & Dashboard.
A9: Materi | B9: Algoritma, Diagram Alir, dan Pseudocode | D9: 5. | E9: Biarkan sel kosong apabila peserta didik belum dinilai; jangan isi angka 0.
D10: 6. | E10: Gunakan hasil pra-tindakan sebagai dasar penyusunan tindakan Siklus I.
A12: Keterangan Indikator Kemampuan Berpikir Algoritmik
A13: Kode | B13: Indikator
A14: IPO | B14: Mengidentifikasi input, proses, dan output.
A15: ALG | B15: Menyusun langkah algoritma secara runtut dan logis.
A16: PER | B16: Menggunakan logika percabangan dengan tepat.
A17: FLW | B17: Merepresentasikan solusi dalam diagram alir (flowchart).
A18: PSD | B18: Merepresentasikan solusi dalam pseudocode.
A19: DBG | B19: Menguji, menemukan, dan memperbaiki kesalahan algoritma.

Sheet Data Diagnostik
A1: DATA PRA-TINDAKAN — ASESMEN DIAGNOSTIK
A2: Masukkan skor 1–4 pada kolom indikator. Kolom Total, Nilai, dan Ketuntasan dihitung otomatis.
A4: No. | B4: Kode Peserta Didik | C4: IPO | D4: Algoritma | E4: Percabangan | F4: Flowchart | G4: Pseudocode | H4: Debugging | I4: Total Skor | J4: Nilai | K4: Ketuntasan | L4: Catatan
A5: 1 | B5: X5-01 | C5: 1 | D5: 2 | E5: 1 | F5: 1 | G5: 1 | H5: 1 | I5: =IF(COUNTA(C5:H5)=0,"",SUM(C5:H5)) -> 7 | J5: =IF(I5="","",ROUND(I5/'Rekap & Dashboard'!$B$7*100,2)) -> 29.17 | K5: =IF(J5="","",IF(J5>='Rekap & Dashboard'!$B$6,"Tuntas","Belum Tuntas")) -> Belum Tuntas
A6: 2 | B6: X5-02 | C6: 1 | D6: 1 | E6: 1 | F6: 1 | G6: 1 | H6: 1 | I6: =IF(COUNTA(C6:H6)=0,"",SUM(C6:H6)) -> 6 | J6: =IF(I6="","",ROUND(I6/'Rekap & Dashboard'!$B$7*100,2)) -> 25 | K6: =IF(J6="","",IF(J6>='Rekap & Dashboard'!$B$6,"Tuntas","Belum Tuntas")) -> Belum Tuntas
A7: 3 | B7: X5-03 | C7: 2 | D7: 2 | E7: 2 | F7: 1 | G7: 1 | H7: 2 | I7: =IF(COUNTA(C7:H7)=0,"",SUM(C7:H7)) -> 10 | J7: =IF(I7="","",ROUND(I7/'Rekap & Dashboard'!$B$7*100,2)) -> 41.67 | K7: =IF(J7="","",IF(J7>='Rekap & Dashboard'!$B$6,"Tuntas","Belum Tuntas")) -> Belum Tuntas
A8: 4 | B8: X5-04 | C8: 2 | D8: 3 | E8: 2 | F8: 1 | G8: 1 | H8: 2 | I8: =IF(COUNTA(C8:H8)=0,"",SUM(C8:H8)) -> 11 | J8: =IF(I8="","",ROUND(I8/'Rekap & Dashboard'!$B$7*100,2)) -> 45.83 | K8: =IF(J8="","",IF(J8>='Rekap & Dashboard'!$B$6,"Tuntas","Belum Tuntas")) -> Belum Tuntas
A9: 5 | B9: X5-05 | C9: 2 | D9: 3 | E9: 2 | F9: 1 | G9: 1 | H9: 2 | I9: =IF(COUNTA(C9:H9)=0,"",SUM(C9:H9)) -> 11 | J9: =IF(I9="","",ROUND(I9/'Rekap & Dashboard'!$B$7*100,2)) -> 45.83 | K9: =IF(J9="","",IF(J9>='Rekap & Dashboard'!$B$6,"Tuntas","Belum Tuntas")) -> Belum Tuntas
A10: 6 | B10: X5-06 | C10: 1 | D10: 1 | E10: 1 | F10: 1 | G10: 1 | H10: 1 | I10: =IF(COUNTA(C10:H10)=0,"",SUM(C10:H10)) -> 6 | J10: =IF(I10="","",ROUND(I10/'Rekap & Dashboard'!$B$7*100,2)) -> 25 | K10: =IF(J10="","",IF(J10>='Rekap & Dashboard'!$B$6,"Tuntas","Belum Tuntas")) -> Belum Tuntas
A11: 7 | B11: X5-07 | C11: 1 | D11: 1 | E11: 1 | F11: 1 | G11: 1 | H11: 1 | I11: =IF(COUNTA(C11:H11)=0,"",SUM(C11:H11)) -> 6 | J11: =IF(I11="","",ROUND(I11/'Rekap & Dashboard'!$B$7*100,2)) -> 25 | K11: =IF(J11="","",IF(J11>='Rekap & Dashboard'!$B$6,"Tuntas","Belum Tuntas")) -> Belum Tuntas
A12: 8 | B12: X5-08 | C12: 2 | D12: 2 | E12: 2 | F12: 1 | G12: 1 | H12: 2 | I12: =IF(COUNTA(C12:H12)=0,"",SUM(C12:H12)) -> 10 | J12: =IF(I12="","",ROUND(I12/'Rekap & Dashboard'!$B$7*100,2)) -> 41.67 | K12: =IF(J12="","",IF(J12>='Rekap & Dashboard'!$B$6,"Tuntas","Belum Tuntas")) -> Belum Tuntas
A13: 9 | B13: X5-09 | C13: 2 | D13: 2 | E13: 2 | F13: 1 | G13: 1 | H13: 2 | I13: =IF(COUNTA(C13:H13)=0,"",SUM(C13:H13)) -> 10 | J13: =IF(I13="","",ROUND(I13/'Rekap & Dashboard'!$B$7*100,2)) -> 41.67 | K13: =IF(J13="","",IF(J13>='Rekap & Dashboard'!$B$6,"Tuntas","Belum Tuntas")) -> Belum Tuntas
A14: 10 | B14: X5-10 | C14: 2 | D14: 3 | E14: 2 | F14: 1 | G14: 1 | H14: 2 | I14: =IF(COUNTA(C14:H14)=0,"",SUM(C14:H14)) -> 11 | J14: =IF(I14="","",ROUND(I14/'Rekap & Dashboard'!$B$7*100,2)) -> 45.83 | K14: =IF(J14="","",IF(J14>='Rekap & Dashboard'!$B$6,"Tuntas","Belum Tuntas")) -> Belum Tuntas
A15: 11 | B15: X5-11 | C15: 2 | D15: 2 | E15: 1 | F15: 1 | G15: 1 | H15: 2 | I15: =IF(COUNTA(C15:H15)=0,"",SUM(C15:H15)) -> 9 | J15: =IF(I15="","",ROUND(I15/'Rekap & Dashboard'!$B$7*100,2)) -> 37.5 | K15: =IF(J15="","",IF(J15>='Rekap & Dashboard'!$B$6,"Tuntas","Belum Tuntas")) -> Belum Tuntas
A16: 12 | B16: X5-12 | C16: 2 | D16: 2 | E16: 1 | F16: 1 | G16: 1 | H16: 2 | I16: =IF(COUNTA(C16:H16)=0,"",SUM(C16:H16)) -> 9 | J16: =IF(I16="","",ROUND(I16/'Rekap & Dashboard'!$B$7*100,2)) -> 37.5 | K16: =IF(J16="","",IF(J16>='Rekap & Dashboard'!$B$6,"Tuntas","Belum Tuntas")) -> Belum Tuntas
... A50: 46 | B50: X5-46 | C50: 4 | D50: 4 | E50: 3 | F50: 2 | G50: 2 | H50: 3 | I50: =IF(COUNTA(C50:H50)=0,"",SUM(C50:H50)) -> 18 | J50: =IF(I50="","",ROUND(I50/'Rekap & Dashboard'!$B$7*100,2)) -> 75 | K50: =IF(J50="","",IF(J50>='Rekap & Dashboard'!$B$6,"Tuntas","Belum Tuntas")) -> Tuntas

Sheet Observasi Kemandirian
A1: LEMBAR PENGOLAHAN OBSERVASI KEMANDIRIAN
A2: Skor: 4 = sangat mandiri, 3 = mandiri, 2 = kurang mandiri, 1 = belum mandiri. | M2: Kode | N2: Indikator Kemandirian
M3: K1 | N3: Memulai mengerjakan tanpa menunggu contoh guru.
A4: No. | B4: Kode Peserta Didik | C4: K1 | D4: K2 | E4: K3 | F4: K4 | G4: K5 | H4: Total | I4: Rata-rata | J4: Kategori | K4: Catatan Observer | M4: K2 | N4: Berusaha memahami masalah secara mandiri.
A5: 1 | B5: X5-01 | C5: 3 | D5: 2 | E5: 1 | F5: 2 | G5: 2 | H5: =IF(COUNTA(C5:G5)=0,"",SUM(C5:G5)) -> 10 | I5: =IF(H5="","",ROUND(H5/5,2)) -> 2 | J5: =IF(I5="","",IF(I5>=3.26,"Sangat Mandiri",IF(I5>=2.51,"Mandiri",IF(I5>=1.76,"Kurang Mandiri","Belum Mandiri")))) -> Kurang Mandiri | M5: K3 | N5: Mencoba menyusun solusi sendiri sebelum meminta bantuan.
A6: 2 | B6: X5-02 | C6: 3 | D6: 1 | E6: 1 | F6: 2 | G6: 3 | H6: =IF(COUNTA(C6:G6)=0,"",SUM(C6:G6)) -> 10 | I6: =IF(H6="","",ROUND(H6/5,2)) -> 2 | J6: =IF(I6="","",IF(I6>=3.26,"Sangat Mandiri",IF(I6>=2.51,"Mandiri",IF(I6>=1.76,"Kurang Mandiri","Belum Mandiri")))) -> Kurang Mandiri | M6: K4 | N6: Memeriksa kembali solusi yang dibuat.
A7: 3 | B7: X5-03 | C7: 3 | D7: 2 | E7: 1 | F7: 2 | G7: 2 | H7: =IF(COUNTA(C7:G7)=0,"",SUM(C7:G7)) -> 10 | I7: =IF(H7="","",ROUND(H7/5,2)) -> 2 | J7: =IF(I7="","",IF(I7>=3.26,"Sangat Mandiri",IF(I7>=2.51,"Mandiri",IF(I7>=1.76,"Kurang Mandiri","Belum Mandiri")))) -> Kurang Mandiri | M7: K5 | N7: Memperbaiki solusi ketika menemukan kesalahan.
A8: 4 | B8: X5-04 | C8: 3 | D8: 2 | E8: 1 | F8: 3 | G8: 3 | H8: =IF(COUNTA(C8:G8)=0,"",SUM(C8:G8)) -> 12 | I8: =IF(H8="","",ROUND(H8/5,2)) -> 2.4 | J8: =IF(I8="","",IF(I8>=3.26,"Sangat Mandiri",IF(I8>=2.51,"Mandiri",IF(I8>=1.76,"Kurang Mandiri","Belum Mandiri")))) -> Kurang Mandiri
A9: 5 | B9: X5-05 | C9: 3 | D9: 2 | E9: 1 | F9: 2 | G9: 2 | H9: =IF(COUNTA(C9:G9)=0,"",SUM(C9:G9)) -> 10 | I9: =IF(H9="","",ROUND(H9/5,2)) -> 2 | J9: =IF(I9="","",IF(I9>=3.26,"Sangat Mandiri",IF(I9>=2.51,"Mandiri",IF(I9>=1.76,"Kurang Mandiri","Belum Mandiri")))) -> Kurang Mandiri
A10: 6 | B10: X5-06 | C10: 3 | D10: 1 | E10: 1 | F10: 2 | G10: 2 | H10: =IF(COUNTA(C10:G10)=0,"",SUM(C10:G10)) -> 9 | I10: =IF(H10="","",ROUND(H10/5,2)) -> 1.8 | J10: =IF(I10="","",IF(I10>=3.26,"Sangat Mandiri",IF(I10>=2.51,"Mandiri",IF(I10>=1.76,"Kurang Mandiri","Belum Mandiri")))) -> Kurang Mandiri
A11: 7 | B11: X5-07 | C11: 3 | D11: 1 | E11: 1 | F11: 3 | G11: 2 | H11: =IF(COUNTA(C11:G11)=0,"",SUM(C11:G11)) -> 10 | I11: =IF(H11="","",ROUND(H11/5,2)) -> 2 | J11: =IF(I11="","",IF(I11>=3.26,"Sangat Mandiri",IF(I11>=2.51,"Mandiri",IF(I11>=1.76,"Kurang Mandiri","Belum Mandiri")))) -> Kurang Mandiri | M11: 21,25,32,42,46
A12: 8 | B12: X5-08 | C12: 3 | D12: 2 | E12: 1 | F12: 2 | G12: 3 | H12: =IF(COUNTA(C12:G12)=0,"",SUM(C12:G12)) -> 11 | I12: =IF(H12="","",ROUND(H12/5,2)) -> 2.2 | J12: =IF(I12="","",IF(I12>=3.26,"Sangat Mandiri",IF(I12>=2.51,"Mandiri",IF(I12>=1.76,"Kurang Mandiri","Belum Mandiri")))) -> Kurang Mandiri
A13: 9 | B13: X5-09 | C13: 3 | D13: 2 | E13: 1 | F13: 2 | G13: 2 | H13: =IF(COUNTA(C13:G13)=0,"",SUM(C13:G13)) -> 10 | I13: =IF(H13="","",ROUND(H13/5,2)) -> 2 | J13: =IF(I13="","",IF(I13>=3.26,"Sangat Mandiri",IF(I13>=2.51,"Mandiri",IF(I13>=1.76,"Kurang Mandiri","Belum Mandiri")))) -> Kurang Mandiri | M13: 2,6,7,17,18,26,27,37,38,44
A14: 10 | B14: X5-10 | C14: 3 | D14: 2 | E14: 1 | F14: 3 | G14: 2 | H14: =IF(COUNTA(C14:G14)=0,"",SUM(C14:G14)) -> 11 | I14: =IF(H14="","",ROUND(H14/5,2)) -> 2.2 | J14: =IF(I14="","",IF(I14>=3.26,"Sangat Mandiri",IF(I14>=2.51,"Mandiri",IF(I14>=1.76,"Kurang Mandiri","Belum Mandiri")))) -> Kurang Mandiri
A15: 11 | B15: X5-11 | C15: 3 | D15: 2 | E15: 1 | F15: 2 | G15: 2 | H15: =IF(COUNTA(C15:G15)=0,"",SUM(C15:G15)) -> 10 | I15: =IF(H15="","",ROUND(H15/5,2)) -> 2 | J15: =IF(I15="","",IF(I15>=3.26,"Sangat Mandiri",IF(I15>=2.51,"Mandiri",IF(I15>=1.76,"Kurang Mandiri","Belum Mandiri")))) -> Kurang Mandiri
A16: 12 | B16: X5-12 | C16: 3 | D16: 2 | E16: 1 | F16: 2 | G16: 3 | H16: =IF(COUNTA(C16:G16)=0,"",SUM(C16:G16)) -> 11 | I16: =IF(H16="","",ROUND(H16/5,2)) -> 2.2 | J16: =IF(I16="","",IF(I16>=3.26,"Sangat Mandiri",IF(I16>=2.51,"Mandiri",IF(I16>=1.76,"Kurang Mandiri","Belum Mandiri")))) -> Kurang Mandiri
A17: 13 | B17: X5-13 | C17: 3 | D17: 2 | E17: 1 | F17: 3 | G17: 3 | H17: =IF(COUNTA(C17:G17)=0,"",SUM(C17:G17)) -> 12 | I17: =IF(H17="","",ROUND(H17/5,2)) -> 2.4 | J17: =IF(I17="","",IF(I17>=3.26,"Sangat Mandiri",IF(I17>=2.51,"Mandiri",IF(I17>=1.76,"Kurang Mandiri","Belum Mandiri")))) -> Kurang Mandiri
A18: 14 | B18: X5-14 | C18: 3 | D18: 2 | E18: 1 | F18: 2 | G18: 2 | H18: =IF(COUNTA(C18:G18)=0,"",SUM(C18:G18)) -> 10 | I18: =IF(H18="","",ROUND(H18/5,2)) -> 2 | J18: =IF(I18="","",IF(I18>=3.26,"Sangat Mandiri",IF(I18>=2.51,"Mandiri",IF(I18>=1.76,"Kurang Mandiri","Belum Mandiri")))) -> Kurang Mandiri
A19: 15 | B19: X5-15 | C19: 3 | D19: 2 | E19: 1 | F19: 3 | G19: 3 | H19: =IF(COUNTA(C19:G19)=0,"",SUM(C19:G19)) -> 12 | I19: =IF(H19="","",ROUND(H19/5,2)) -> 2.4 | J19: =IF(I19="","",IF(I19>=3.26,"Sangat Mandiri",IF(I19>=2.51,"Mandiri",IF(I19>=1.76,"Kurang Mandiri","Belum Mandiri")))) -> Kurang Mandiri
A20: 16 | B20: X5-16 | C20: 3 | D20: 2 | E20: 1 | F20: 2 | G20: 2 | H20: =IF(COUNTA(C20:G20)=0,"",SUM(C20:G20)) -> 10 | I20: =IF(H20="","",ROUND(H20/5,2)) -> 2 | J20: =IF(I20="","",IF(I20>=3.26,"Sangat Mandiri",IF(I20>=2.51,"Mandiri",IF(I20>=1.76,"Kurang Mandiri","Belum Mandiri")))) -> Kurang Mandiri
A21: 17 | B21: X5-17 | C21: 3 | D21: 1 | E21: 1 | F21: 2 | G21: 2 | H21: =IF(COUNTA(C21:G21)=0,"",SUM(C21:G21)) -> 9 | I21: =IF(H21="","",ROUND(H21/5,2)) -> 1.8 | J21: =IF(I21="","",IF(I21>=3.26,"Sangat Mandiri",IF(I21>=2.51,"Mandiri",IF(I21>=1.76,"Kurang Mandiri","Belum Mandiri")))) -> Kurang Mandiri
A22: 18 | B22: X5-18 | C22: 3 | D22: 1 | E22: 1 | F22: 2 | G22: 2 | H22: =IF(COUNTA(C22:G22)=0,"",SUM(C22:G22)) -> 9 | I22: =IF(H22="","",ROUND(H22/5,2)) -> 1.8 | J22: =IF(I22="","",IF(I22>=3.26,"Sangat Mandiri",IF(I22>=2.51,"Mandiri",IF(I22>=1.76,"Kurang Mandiri","Belum Mandiri")))) -> Kurang Mandiri
A23: 19 | B23: X5-19 | C23: 3 | D23: 2 | E23: 1 | F23: 2 | G23: 2 | H23: =IF(COUNTA(C23:G23)=0,"",SUM(C23:G23)) -> 10 | I23: =IF(H23="","",ROUND(H23/5,2)) -> 2 | J23: =IF(I23="","",IF(I23>=3.26,"Sangat Mandiri",IF(I23>=2.51,"Mandiri",IF(I23>=1.76,"Kurang Mandiri","Belum Mandiri")))) -> Kurang Mandiri
A24: 20 | B24: X5-20 | C24: 3 | D24: 2 | E24: 1 | F24: 2 | G24: 2 | H24: =IF(COUNTA(C24:G24)=0,"",SUM(C24:G24)) -> 10 | I24: =IF(H24="","",ROUND(H24/5,2)) -> 2 | J24: =IF(I24="","",IF(I24>=3.26,"Sangat Mandiri",IF(I24>=2.51,"Mandiri",IF(I24>=1.76,"Kurang Mandiri","Belum Mandiri")))) -> Kurang Mandiri
A25: 21 | B25: X5-21 | C25: 3 | D25: 3 | E25: 3 | F25: 3 | G25: 3 | H25: =IF(COUNTA(C25:G25)=0,"",SUM(C25:G25)) -> 15 | I25: =IF(H25="","",ROUND(H25/5,2)) -> 3 | J25: =IF(I25="","",IF(I25>=3.26,"Sangat Mandiri",IF(I25>=2.51,"Mandiri",IF(I25>=1.76,"Kurang Mandiri","Belum Mandiri")))) -> Mandiri
... A50: 46 | B50: X5-46 | C50: 3 | D50: 3 | E50: 3 | F50: 3 | G50: 3 | H50: =IF(COUNTA(C50:G50)=0,"",SUM(C50:G50)) -> 15 | I50: =IF(H50="","",ROUND(H50/5,2)) -> 3 | J50: =IF(I50="","",IF(I50>=3.26,"Sangat Mandiri",IF(I50>=2.51,"Mandiri",IF(I50>=1.76,"Kurang Mandiri","Belum Mandiri")))) -> Mandiri

Sheet Rekap & Dashboard
A1: REKAPITULASI & DASHBOARD DATA PRA-TINDAKAN
A3: Parameter | B3: Nilai | D3: Ringkasan Diagnostik | E3: Hasil
A4: Jumlah Peserta Didik | B4: 46 | D4: Peserta Didik Dinilai | E4: =COUNT('Data Diagnostik'!J5:J50) -> 46
A5: Fase / Kelas | B5: E / X-5 | D5: Rata-rata Kelas | E5: =IFERROR(ROUND(AVERAGE('Data Diagnostik'!J5:J50),2),"") -> 39.86
A6: KKTP | B6: 75 | D6: Tuntas | E6: =COUNTIF('Data Diagnostik'!K5:K50,"Tuntas") -> 5
A7: Skor Maksimum Diagnostik | B7: 24 | D7: Belum Tuntas | E7: =COUNTIF('Data Diagnostik'!K5:K50,"Belum Tuntas") -> 41
D8: Persentase Ketuntasan | E8: =IF(E4=0,"",E6/E4) -> 0.10869565
A10: Indikator | B10: Rata-rata Skor (1–4) | C10: Capaian (%) | D10: Interpretasi | F10: Ringkasan Kemandirian | G10: Nilai | H10: Keterangan
A11: IPO | B11: =IFERROR(ROUND(AVERAGE('Data Diagnostik'!C5:C50),2),"") -> 1.85 | C11: =IF(B11="","",B11/4) -> 0.4625 | D11: =IF(B11="","",IF(B11>=3.26,"Sangat Baik",IF(B11>=2.51,"Baik",IF(B11>=1.76,"Cukup","Perlu Bimbingan")))) -> Cukup | F11: Peserta Didik Diobservasi | G11: =COUNT('Observasi Kemandirian'!I5:I50) -> 46 | H11: Jumlah data
A12: Algoritma | B12: =IFERROR(ROUND(AVERAGE('Data Diagnostik'!D5:D50),2),"") -> 2.15 | C12: =IF(B12="","",B12/4) -> 0.5375 | D12: =IF(B12="","",IF(B12>=3.26,"Sangat Baik",IF(B12>=2.51,"Baik",IF(B12>=1.76,"Cukup","Perlu Bimbingan")))) -> Cukup | F12: Rata-rata Kemandirian | G12: =IFERROR(ROUND(AVERAGE('Observasi Kemandirian'!I5:I50),2),"") -> 2.14 | H12: Skala 1–4
A13: Percabangan | B13: =IFERROR(ROUND(AVERAGE('Data Diagnostik'!E5:E50),2),"") -> 1.63 | C13: =IF(B13="","",B13/4) -> 0.4075 | D13: =IF(B13="","",IF(B13>=3.26,"Sangat Baik",IF(B13>=2.51,"Baik",IF(B13>=1.76,"Cukup","Perlu Bimbingan")))) -> Perlu Bimbingan | F13: Sangat Mandiri | G13: =COUNTIF('Observasi Kemandirian'!J5:J50,"Sangat Mandiri") -> 0 | H13: =IF(G11=0,"",G13/G11) -> 0
A14: Flowchart | B14: =IFERROR(ROUND(AVERAGE('Data Diagnostik'!F5:F50),2),"") -> 1.13 | C14: =IF(B14="","",B14/4) -> 0.2825 | D14: =IF(B14="","",IF(B14>=3.26,"Sangat Baik",IF(B14>=2.51,"Baik",IF(B14>=1.76,"Cukup","Perlu Bimbingan")))) -> Perlu Bimbingan | F14: Mandiri | G14: =COUNTIF('Observasi Kemandirian'!J5:J50,"Mandiri") -> 4 | H14: =IF(G11=0,"",G14/G11) -> 0.086956522
A15: Pseudocode | B15: =IFERROR(ROUND(AVERAGE('Data Diagnostik'!G5:G50),2),"") -> 1.11 | C15: =IF(B15="","",B15/4) -> 0.2775 | D15: =IF(B15="","",IF(B15>=3.26,"Sangat Baik",IF(B15>=2.51,"Baik",IF(B15>=1.76,"Cukup","Perlu Bimbingan")))) -> Perlu Bimbingan | F15: Kurang Mandiri | G15: =COUNTIF('Observasi Kemandirian'!J5:J50,"Kurang Mandiri") -> 42 | H15: =IF(G11=0,"",G15/G11) -> 0.91304348
A16: Debugging | B16: =IFERROR(ROUND(AVERAGE('Data Diagnostik'!H5:H50),2),"") -> 1.7 | C16: =IF(B16="","",B16/4) -> 0.425 | D16: =IF(B16="","",IF(B16>=3.26,"Sangat Baik",IF(B16>=2.51,"Baik",IF(B16>=1.76,"Cukup","Perlu Bimbingan")))) -> Perlu Bimbingan | F16: Belum Mandiri | G16: =COUNTIF('Observasi Kemandirian'!J5:J50,"Belum Mandiri") -> 0 | H16: =IF(G11=0,"",G16/G11) -> 0
J18: Status | K18: Jumlah
J19: Tuntas | K19: =E6 -> 5
J20: Belum Tuntas | K20: =E7 -> 41
A22: Kerangka Narasi Analisis Pra-Tindakan | J22: Tuntas
A23: Setelah data diisi, gunakan ringkasan pada dashboard untuk menyusun narasi: (1) jumlah peserta didik yang mengikuti asesmen; (2) nilai rata-rata kelas; (3) jumlah dan persentase ketuntasan berdasarkan KKTP 75; (4) indikator kemampuan berpikir algoritmik yang paling kuat dan paling lemah; (5) tingkat kemandirian peserta didik; serta (6) implikasi temuan tersebut terhadap rancangan tindakan Problem Based Learning pada Siklus I. | J23: Belum Tuntas

Sheet Petunjuk Siklus I
A1: PETUNJUK PENGOLAHAN DATA SIKLUS I & PERBANDINGAN
A3: Parameter Analisis | B3: Nilai | D3: Langkah Penggunaan | E3: Keterangan
A4: Jumlah peserta didik kelas | B4: 46 | D4: 1 | E4: Isi kolom Kehadiran dan skor 1–4 pada sheet Data Siklus I.
A5: KKTP | B5: 75 | D5: 2 | E5: Peserta yang sakit/izin/dispensasi/alpa tidak diberi nilai 0; biarkan skor kosong.
A6: Skor maksimum asesmen | B6: 24 | D6: 3 | E6: Isi sheet Obs Kemandirian S1 menggunakan indikator K1–K5 yang sama dengan pra-tindakan.
A7: Target ketuntasan klasikal | B7: 0.7 | D7: 4 | E7: Sheet Refleksi Siklus I bersifat pendukung; masukkan skor refleksi jika ingin dianalisis.
A8: Batas minimal kehadiran pelaksanaan | B8: 0.8 | D8: 5 | E8: Perbandingan Pra-S1 hanya menganalisis peserta didik dengan data Siklus I lengkap.
A9: Target rata-rata Flowchart | B9: 2.5 | D9: 6 | E9: Dashboard Siklus I menghitung hasil dan indikator keberhasilan secara otomatis.
A10: Target rata-rata Pseudocode | B10: 2.5 | D10: 7 | E10: Jangan mengubah rumus pada kolom otomatis. Masukkan data hanya pada sel input.
A11: Skor maksimum tiap indikator | B11: 4
A12: Ambang Sangat Mandiri | B12: 3.5
A13: Ambang Mandiri | B13: 2.5
A14: Ambang Kurang Mandiri | B14: 1.5
A15: Skor maksimum kemandirian | B15: 4
A17: KRITERIA KEBERHASILAN
A18: 1. | B18: Sekurang-kurangnya 70% peserta didik dengan data berpasangan mencapai nilai ≥ KKTP.
A19: 2. | B19: Rata-rata kemampuan berpikir algoritmik Siklus I meningkat dibandingkan pra-tindakan pada peserta yang sama.
A20: 3. | B20: Rata-rata Flowchart Siklus I mencapai minimal 2,50 dari skala 4.
A21: 4. | B21: Rata-rata Pseudocode Siklus I mencapai minimal 2,50 dari skala 4.
A22: Pendukung | B22: Rata-rata kemandirian meningkat dan jumlah kategori Mandiri/Sangat Mandiri bertambah.
A23: Catatan | B23: Pelaksanaan diupayakan saat minimal 80% dari 46 peserta didik hadir (minimal 37 peserta didik).

Sheet Data Siklus I
A1: DATA SIKLUS I — ASESMEN INDIVIDU AKHIR
A2: Isi Kehadiran dan skor 1–4 pada enam indikator. Total, nilai, ketuntasan, dan status data dihitung otomatis.
A4: No. | B4: Kode Peserta Didik | C4: Kehadiran | D4: IPO | E4: Algoritma | F4: Percabangan | G4: Flowchart | H4: Pseudocode | I4: Debugging | J4: Total Skor | K4: Nilai | L4: Ketuntasan | M4: Status Data | N4: Catatan
A5: 1 | B5: X5-01 | C5: Hadir | D5: 3 | E5: 3 | F5: 3 | G5: 3 | H5: 3 | I5: 3 | J5: =IF(AND(C5="Hadir",COUNT(D5:I5)=6),SUM(D5:I5),"") -> 18 | K5: =IF(J5="","",ROUND(J5/'Petunjuk Siklus I'!$B$6*100,2)) -> 75 | L5: =IF(K5="","",IF(K5>='Petunjuk Siklus I'!$B$5,"Tuntas","Belum Tuntas")) -> Tuntas | M5: =IF(C5="","",IF(C5="Hadir",IF(COUNT(D5:I5)=6,"Lengkap","Belum Lengkap"),"Tidak Dianalisis")) -> Lengkap
A6: 2 | B6: X5-02 | C6: Hadir | D6: 4 | E6: 3 | F6: 4 | G6: 1 | H6: 4 | I6: 4 | J6: =IF(AND(C6="Hadir",COUNT(D6:I6)=6),SUM(D6:I6),"") -> 20 | K6: =IF(J6="","",ROUND(J6/'Petunjuk Siklus I'!$B$6*100,2)) -> 83.33 | L6: =IF(K6="","",IF(K6>='Petunjuk Siklus I'!$B$5,"Tuntas","Belum Tuntas")) -> Tuntas | M6: =IF(C6="","",IF(C6="Hadir",IF(COUNT(D6:I6)=6,"Lengkap","Belum Lengkap"),"Tidak Dianalisis")) -> Lengkap
A7: 3 | B7: X5-03 | C7: Hadir | D7: 4 | E7: 3 | F7: 3 | G7: 3 | H7: 2 | I7: 0 | J7: =IF(AND(C7="Hadir",COUNT(D7:I7)=6),SUM(D7:I7),"") -> 15 | K7: =IF(J7="","",ROUND(J7/'Petunjuk Siklus I'!$B$6*100,2)) -> 62.5 | L7: =IF(K7="","",IF(K7>='Petunjuk Siklus I'!$B$5,"Tuntas","Belum Tuntas")) -> Belum Tuntas | M7: =IF(C7="","",IF(C7="Hadir",IF(COUNT(D7:I7)=6,"Lengkap","Belum Lengkap"),"Tidak Dianalisis")) -> Lengkap
A8: 4 | B8: X5-04 | C8: Hadir | D8: 3 | E8: 3 | F8: 3 | G8: 3 | H8: 3 | I8: 3 | J8: =IF(AND(C8="Hadir",COUNT(D8:I8)=6),SUM(D8:I8),"") -> 18 | K8: =IF(J8="","",ROUND(J8/'Petunjuk Siklus I'!$B$6*100,2)) -> 75 | L8: =IF(K8="","",IF(K8>='Petunjuk Siklus I'!$B$5,"Tuntas","Belum Tuntas")) -> Tuntas | M8: =IF(C8="","",IF(C8="Hadir",IF(COUNT(D8:I8)=6,"Lengkap","Belum Lengkap"),"Tidak Dianalisis")) -> Lengkap
A9: 5 | B9: X5-05 | C9: Hadir | D9: 4 | E9: 4 | F9: 4 | G9: 4 | H9: 4 | I9: 4 | J9: =IF(AND(C9="Hadir",COUNT(D9:I9)=6),SUM(D9:I9),"") -> 24 | K9: =IF(J9="","",ROUND(J9/'Petunjuk Siklus I'!$B$6*100,2)) -> 100 | L9: =IF(K9="","",IF(K9>='Petunjuk Siklus I'!$B$5,"Tuntas","Belum Tuntas")) -> Tuntas | M9: =IF(C9="","",IF(C9="Hadir",IF(COUNT(D9:I9)=6,"Lengkap","Belum Lengkap"),"Tidak Dianalisis")) -> Lengkap
A10: 6 | B10: X5-06 | C10: Hadir | D10: 4 | E10: 3 | F10: 3 | G10: 1 | H10: 3 | I10: 4 | J10: =IF(AND(C10="Hadir",COUNT(D10:I10)=6),SUM(D10:I10),"") -> 18 | K10: =IF(J10="","",ROUND(J10/'Petunjuk Siklus I'!$B$6*100,2)) -> 75 | L10: =IF(K10="","",IF(K10>='Petunjuk Siklus I'!$B$5,"Tuntas","Belum Tuntas")) -> Tuntas | M10: =IF(C10="","",IF(C10="Hadir",IF(COUNT(D10:I10)=6,"Lengkap","Belum Lengkap"),"Tidak Dianalisis")) -> Lengkap
A11: 7 | B11: X5-07 | C11: Hadir | D11: 3 | E11: 3 | F11: 3 | G11: 3 | H11: 3 | I11: 3 | J11: =IF(AND(C11="Hadir",COUNT(D11:I11)=6),SUM(D11:I11),"") -> 18 | K11: =IF(J11="","",ROUND(J11/'Petunjuk Siklus I'!$B$6*100,2)) -> 75 | L11: =IF(K11="","",IF(K11>='Petunjuk Siklus I'!$B$5,"Tuntas","Belum Tuntas")) -> Tuntas | M11: =IF(C11="","",IF(C11="Hadir",IF(COUNT(D11:I11)=6,"Lengkap","Belum Lengkap"),"Tidak Dianalisis")) -> Lengkap
A12: 8 | B12: X5-08 | C12: Hadir | D12: 4 | E12: 4 | F12: 1 | G12: 1 | H12: 0 | I12: 4 | J12: =IF(AND(C12="Hadir",COUNT(D12:I12)=6),SUM(D12:I12),"") -> 14 | K12: =IF(J12="","",ROUND(J12/'Petunjuk Siklus I'!$B$6*100,2)) -> 58.33 | L12: =IF(K12="","",IF(K12>='Petunjuk Siklus I'!$B$5,"Tuntas","Belum Tuntas")) -> Belum Tuntas | M12: =IF(C12="","",IF(C12="Hadir",IF(COUNT(D12:I12)=6,"Lengkap","Belum Lengkap"),"Tidak Dianalisis")) -> Lengkap
A13: 9 | B13: X5-09 | C13: Hadir | D13: 4 | E13: 4 | F13: 4 | G13: 3 | H13: 4 | I13: 4 | J13: =IF(AND(C13="Hadir",COUNT(D13:I13)=6),SUM(D13:I13),"") -> 23 | K13: =IF(J13="","",ROUND(J13/'Petunjuk Siklus I'!$B$6*100,2)) -> 95.83 | L13: =IF(K13="","",IF(K13>='Petunjuk Siklus I'!$B$5,"Tuntas","Belum Tuntas")) -> Tuntas | M13: =IF(C13="","",IF(C13="Hadir",IF(COUNT(D13:I13)=6,"Lengkap","Belum Lengkap"),"Tidak Dianalisis")) -> Lengkap
A14: 10 | B14: X5-10 | C14: Hadir | D14: 4 | E14: 4 | F14: 3 | G14: 3 | H14: 0 | I14: 0 | J14: =IF(AND(C14="Hadir",COUNT(D14:I14)=6),SUM(D14:I14),"") -> 14 | K14: =IF(J14="","",ROUND(J14/'Petunjuk Siklus I'!$B$6*100,2)) -> 58.33 | L14: =IF(K14="","",IF(K14>='Petunjuk Siklus I'!$B$5,"Tuntas","Belum Tuntas")) -> Belum Tuntas | M14: =IF(C14="","",IF(C14="Hadir",IF(COUNT(D14:I14)=6,"Lengkap","Belum Lengkap"),"Tidak Dianalisis")) -> Lengkap
A15: 11 | B15: X5-11 | C15: Hadir | D15: 4 | E15: 2 | F15: 4 | G15: 4 | H15: 0 | I15: 0 | J15: =IF(AND(C15="Hadir",COUNT(D15:I15)=6),SUM(D15:I15),"") -> 14 | K15: =IF(J15="","",ROUND(J15/'Petunjuk Siklus I'!$B$6*100,2)) -> 58.33 | L15: =IF(K15="","",IF(K15>='Petunjuk Siklus I'!$B$5,"Tuntas","Belum Tuntas")) -> Belum Tuntas | M15: =IF(C15="","",IF(C15="Hadir",IF(COUNT(D15:I15)=6,"Lengkap","Belum Lengkap"),"Tidak Dianalisis")) -> Lengkap
A16: 12 | B16: X5-12 | C16: Hadir | D16: 4 | E16: 4 | F16: 4 | G16: 3 | H16: 4 | I16: 0 | J16: =IF(AND(C16="Hadir",COUNT(D16:I16)=6),SUM(D16:I16),"") -> 19 | K16: =IF(J16="","",ROUND(J16/'Petunjuk Siklus I'!$B$6*100,2)) -> 79.17 | L16: =IF(K16="","",IF(K16>='Petunjuk Siklus I'!$B$5,"Tuntas","Belum Tuntas")) -> Tuntas | M16: =IF(C16="","",IF(C16="Hadir",IF(COUNT(D16:I16)=6,"Lengkap","Belum Lengkap"),"Tidak Dianalisis")) -> Lengkap
... A32: 28 | B32: X5-28 | C32: Hadir | D32: 4 | E32: 4 | F32: 4 | G32: 4 | H32: 4 | I32: 4 | J32: =IF(AND(C32="Hadir",COUNT(D32:I32)=6),SUM(D32:I32),"") -> 24 | K32: =IF(J32="","",ROUND(J32/'Petunjuk Siklus I'!$B$6*100,2)) -> 100 | L32: =IF(K32="","",IF(K32>='Petunjuk Siklus I'!$B$5,"Tuntas","Belum Tuntas")) -> Tuntas | M32: =IF(C32="","",IF(C32="Hadir",IF(COUNT(D32:I32)=6,"Lengkap","Belum Lengkap"),"Tidak Dianalisis")) -> Lengkap
A33: 29 | B33: X5-29 | C33: Sakit | J33: =IF(AND(C33="Hadir",COUNT(D33:I33)=6),SUM(D33:I33),"") | K33: =IF(J33="","",ROUND(J33/'Petunjuk Siklus I'!$B$6*100,2)) | L33: =IF(K33="","",IF(K33>='Petunjuk Siklus I'!$B$5,"Tuntas","Belum Tuntas")) | M33: =IF(C33="","",IF(C33="Hadir",IF(COUNT(D33:I33)=6,"Lengkap","Belum Lengkap"),"Tidak Dianalisis")) -> Tidak Dianalisis
A34: 30 | B34: X5-30 | C34: Sakit | J34: =IF(AND(C34="Hadir",COUNT(D34:I34)=6),SUM(D34:I34),"") | K34: =IF(J34="","",ROUND(J34/'Petunjuk Siklus I'!$B$6*100,2)) | L34: =IF(K34="","",IF(K34>='Petunjuk Siklus I'!$B$5,"Tuntas","Belum Tuntas")) | M34: =IF(C34="","",IF(C34="Hadir",IF(COUNT(D34:I34)=6,"Lengkap","Belum Lengkap"),"Tidak Dianalisis")) -> Tidak Dianalisis
A35: 31 | B35: X5-31 | C35: Hadir | D35: 4 | E35: 4 | F35: 4 | G35: 3 | H35: 4 | I35: 0 | J35: =IF(AND(C35="Hadir",COUNT(D35:I35)=6),SUM(D35:I35),"") -> 19 | K35: =IF(J35="","",ROUND(J35/'Petunjuk Siklus I'!$B$6*100,2)) -> 79.17 | L35: =IF(K35="","",IF(K35>='Petunjuk Siklus I'!$B$5,"Tuntas","Belum Tuntas")) -> Tuntas | M35: =IF(C35="","",IF(C35="Hadir",IF(COUNT(D35:I35)=6,"Lengkap","Belum Lengkap"),"Tidak Dianalisis")) -> Lengkap
A36: 32 | B36: X5-32 | C36: Hadir | D36: 4 | E36: 4 | F36: 4 | G36: 3 | H36: 3 | I36: 4 | J36: =IF(AND(C36="Hadir",COUNT(D36:I36)=6),SUM(D36:I36),"") -> 22 | K36: =IF(J36="","",ROUND(J36/'Petunjuk Siklus I'!$B$6*100,2)) -> 91.67 | L36: =IF(K36="","",IF(K36>='Petunjuk Siklus I'!$B$5,"Tuntas","Belum Tuntas")) -> Tuntas | M36: =IF(C36="","",IF(C36="Hadir",IF(COUNT(D36:I36)=6,"Lengkap","Belum Lengkap"),"Tidak Dianalisis")) -> Lengkap
A37: 33 | B37: X5-33 | C37: Dispensasi | D37: 4 | E37: 4 | F37: 4 | G37: 1 | H37: 4 | I37: 4 | J37: =IF(AND(C37="Hadir",COUNT(D37:I37)=6),SUM(D37:I37),"") | K37: =IF(J37="","",ROUND(J37/'Petunjuk Siklus I'!$B$6*100,2)) | L37: =IF(K37="","",IF(K37>='Petunjuk Siklus I'!$B$5,"Tuntas","Belum Tuntas")) | M37: =IF(C37="","",IF(C37="Hadir",IF(COUNT(D37:I37)=6,"Lengkap","Belum Lengkap"),"Tidak Dianalisis")) -> Tidak Dianalisis
A38: 34 | B38: X5-34 | C38: Hadir | D38: 3 | E38: 3 | F38: 4 | G38: 2 | H38: 2 | I38: 0 | J38: =IF(AND(C38="Hadir",COUNT(D38:I38)=6),SUM(D38:I38),"") -> 14 | K38: =IF(J38="","",ROUND(J38/'Petunjuk Siklus I'!$B$6*100,2)) -> 58.33 | L38: =IF(K38="","",IF(K38>='Petunjuk Siklus I'!$B$5,"Tuntas","Belum Tuntas")) -> Belum Tuntas | M38: =IF(C38="","",IF(C38="Hadir",IF(COUNT(D38:I38)=6,"Lengkap","Belum Lengkap"),"Tidak Dianalisis")) -> Lengkap
A39: 35 | B39: X5-35 | C39: Hadir | D39: 4 | E39: 4 | F39: 4 | G39: 3 | H39: 4 | I39: 4 | J39: =IF(AND(C39="Hadir",COUNT(D39:I39)=6),SUM(D39:I39),"") -> 23 | K39: =IF(J39="","",ROUND(J39/'Petunjuk Siklus I'!$B$6*100,2)) -> 95.83 | L39: =IF(K39="","",IF(K39>='Petunjuk Siklus I'!$B$5,"Tuntas","Belum Tuntas")) -> Tuntas | M39: =IF(C39="","",IF(C39="Hadir",IF(COUNT(D39:I39)=6,"Lengkap","Belum Lengkap"),"Tidak Dianalisis")) -> Lengkap
A40: 36 | B40: X5-36 | C40: Hadir | D40: 4 | E40: 4 | F40: 4 | G40: 4 | H40: 3 | I40: 4 | J40: =IF(AND(C40="Hadir",COUNT(D40:I40)=6),SUM(D40:I40),"") -> 23 | K40: =IF(J40="","",ROUND(J40/'Petunjuk Siklus I'!$B$6*100,2)) -> 95.83 | L40: =IF(K40="","",IF(K40>='Petunjuk Siklus I'!$B$5,"Tuntas","Belum Tuntas")) -> Tuntas | M40: =IF(C40="","",IF(C40="Hadir",IF(COUNT(D40:I40)=6,"Lengkap","Belum Lengkap"),"Tidak Dianalisis")) -> Lengkap
A41: 37 | B41: X5-37 | C41: Hadir | D41: 4 | E41: 3 | F41: 4 | G41: 1 | H41: 3 | I41: 4 | J41: =IF(AND(C41="Hadir",COUNT(D41:I41)=6),SUM(D41:I41),"") -> 19 | K41: =IF(J41="","",ROUND(J41/'Petunjuk Siklus I'!$B$6*100,2)) -> 79.17 | L41: =IF(K41="","",IF(K41>='Petunjuk Siklus I'!$B$5,"Tuntas","Belum Tuntas")) -> Tuntas | M41: =IF(C41="","",IF(C41="Hadir",IF(COUNT(D41:I41)=6,"Lengkap","Belum Lengkap"),"Tidak Dianalisis")) -> Lengkap
A42: 38 | B42: X5-38 | C42: Hadir | D42: 4 | E42: 4 | F42: 4 | G42: 2 | H42: 0 | I42: 0 | J42: =IF(AND(C42="Hadir",COUNT(D42:I42)=6),SUM(D42:I42),"") -> 14 | K42: =IF(J42="","",ROUND(J42/'Petunjuk Siklus I'!$B$6*100,2)) -> 58.33 | L42: =IF(K42="","",IF(K42>='Petunjuk Siklus I'!$B$5,"Tuntas","Belum Tuntas")) -> Belum Tuntas | M42: =IF(C42="","",IF(C42="Hadir",IF(COUNT(D42:I42)=6,"Lengkap","Belum Lengkap"),"Tidak Dianalisis")) -> Lengkap
A43: 39 | B43: X5-39 | C43: Hadir | D43: 4 | E43: 4 | F43: 4 | G43: 4 | H43: 4 | I43: 4 | J43: =IF(AND(C43="Hadir",COUNT(D43:I43)=6),SUM(D43:I43),"") -> 24 | K43: =IF(J43="","",ROUND(J43/'Petunjuk Siklus I'!$B$6*100,2)) -> 100 | L43: =IF(K43="","",IF(K43>='Petunjuk Siklus I'!$B$5,"Tuntas","Belum Tuntas")) -> Tuntas | M43: =IF(C43="","",IF(C43="Hadir",IF(COUNT(D43:I43)=6,"Lengkap","Belum Lengkap"),"Tidak Dianalisis")) -> Lengkap
A44: 40 | B44: X5-40 | C44: Hadir | D44: 4 | E44: 4 | F44: 4 | G44: 3 | H44: 2 | I44: 2 | J44: =IF(AND(C44="Hadir",COUNT(D44:I44)=6),SUM(D44:I44),"") -> 19 | K44: =IF(J44="","",ROUND(J44/'Petunjuk Siklus I'!$B$6*100,2)) -> 79.17 | L44: =IF(K44="","",IF(K44>='Petunjuk Siklus I'!$B$5,"Tuntas","Belum Tuntas")) -> Tuntas | M44: =IF(C44="","",IF(C44="Hadir",IF(COUNT(D44:I44)=6,"Lengkap","Belum Lengkap"),"Tidak Dianalisis")) -> Lengkap
A45: 41 | B45: X5-41 | C45: Hadir | D45: 4 | E45: 4 | F45: 4 | G45: 2 | H45: 2 | I45: 2 | J45: =IF(AND(C45="Hadir",COUNT(D45:I45)=6),SUM(D45:I45),"") -> 18 | K45: =IF(J45="","",ROUND(J45/'Petunjuk Siklus I'!$B$6*100,2)) -> 75 | L45: =IF(K45="","",IF(K45>='Petunjuk Siklus I'!$B$5,"Tuntas","Belum Tuntas")) -> Tuntas | M45: =IF(C45="","",IF(C45="Hadir",IF(COUNT(D45:I45)=6,"Lengkap","Belum Lengkap"),"Tidak Dianalisis")) -> Lengkap
A46: 42 | B46: X5-42 | C46: Hadir | D46: 3 | E46: 4 | F46: 4 | G46: 3 | H46: 4 | I46: 4 | J46: =IF(AND(C46="Hadir",COUNT(D46:I46)=6),SUM(D46:I46),"") -> 22 | K46: =IF(J46="","",ROUND(J46/'Petunjuk Siklus I'!$B$6*100,2)) -> 91.67 | L46: =IF(K46="","",IF(K46>='Petunjuk Siklus I'!$B$5,"Tuntas","Belum Tuntas")) -> Tuntas | M46: =IF(C46="","",IF(C46="Hadir",IF(COUNT(D46:I46)=6,"Lengkap","Belum Lengkap"),"Tidak Dianalisis")) -> Lengkap
... A50: 46 | B50: X5-46 | C50: Hadir | D50: 3 | E50: 3 | F50: 4 | G50: 4 | H50: 4 | I50: 4 | J50: =IF(AND(C50="Hadir",COUNT(D50:I50)=6),SUM(D50:I50),"") -> 22 | K50: =IF(J50="","",ROUND(J50/'Petunjuk Siklus I'!$B$6*100,2)) -> 91.67 | L50: =IF(K50="","",IF(K50>='Petunjuk Siklus I'!$B$5,"Tuntas","Belum Tuntas")) -> Tuntas | M50: =IF(C50="","",IF(C50="Hadir",IF(COUNT(D50:I50)=6,"Lengkap","Belum Lengkap"),"Tidak Dianalisis")) -> Lengkap
L52: Lengkap | M52: =COUNTIF(DataSiklusITable[Status Data],"Lengkap") -> 41
L53: Belum Lengkap | M53: =COUNTIF(DataSiklusITable[Status Data],"Belum Lengkap") -> 0
L54: Tidak Dianalisis | M54: =COUNTIF(DataSiklusITable[Status Data],"Tidak Dianalisis") -> 5
L55: Total | M55: =SUM(M52:M54) -> 46

Sheet Obs Kemandirian S1
A1: PENGOLAHAN OBSERVASI KEMANDIRIAN — SIKLUS I
A2: Gunakan indikator K1–K5 yang sama dengan pra-tindakan. Peserta tidak hadir tidak diberi skor 0.
O3: Kode | P3: Indikator Kemandirian
A4: No. | B4: Kode Peserta Didik | C4: Kehadiran | D4: K1 | E4: K2 | F4: K3 | G4: K4 | H4: K5 | I4: Total | J4: Rata-rata | K4: Kategori | L4: Status Data | M4: Catatan Observer | O4: K1 | P4: Memulai mengerjakan tanpa menunggu contoh guru.
A5: 1 | B5: X5-01 | C5: Hadir | D5: 4 | E5: 3 | F5: 2 | G5: 3 | H5: 3 | I5: =IF(AND(C5="Hadir",COUNT(D5:H5)=5),SUM(D5:H5),"") -> 15 | J5: =IF(I5="","",ROUND(I5/5,2)) -> 3 | K5: =IF(J5="","",IF(J5>='Petunjuk Siklus I'!$B$12,"Sangat Mandiri",IF(J5>='Petunjuk Siklus I'!$B$13,"Mandiri",IF(J5>='Petunjuk Siklus I'!$B$14,"Kurang Mandiri","Belum Mandiri")))) -> Mandiri | L5: =IF(C5="","",IF(C5="Hadir",IF(COUNT(D5:H5)=5,"Lengkap","Belum Lengkap"),"Tidak Dianalisis")) -> Lengkap | O5: K2 | P5: Berusaha memahami masalah secara mandiri.
A6: 2 | B6: X5-02 | C6: Hadir | D6: 4 | E6: 2 | F6: 2 | G6: 3 | H6: 4 | I6: =IF(AND(C6="Hadir",COUNT(D6:H6)=5),SUM(D6:H6),"") -> 15 | J6: =IF(I6="","",ROUND(I6/5,2)) -> 3 | K6: =IF(J6="","",IF(J6>='Petunjuk Siklus I'!$B$12,"Sangat Mandiri",IF(J6>='Petunjuk Siklus I'!$B$13,"Mandiri",IF(J6>='Petunjuk Siklus I'!$B$14,"Kurang Mandiri","Belum Mandiri")))) -> Mandiri | L6: =IF(C6="","",IF(C6="Hadir",IF(COUNT(D6:H6)=5,"Lengkap","Belum Lengkap"),"Tidak Dianalisis")) -> Lengkap | O6: K3 | P6: Mencoba menyusun solusi sendiri sebelum meminta bantuan.
A7: 3 | B7: X5-03 | C7: Hadir | D7: 4 | E7: 3 | F7: 2 | G7: 3 | H7: 3 | I7: =IF(AND(C7="Hadir",COUNT(D7:H7)=5),SUM(D7:H7),"") -> 15 | J7: =IF(I7="","",ROUND(I7/5,2)) -> 3 | K7: =IF(J7="","",IF(J7>='Petunjuk Siklus I'!$B$12,"Sangat Mandiri",IF(J7>='Petunjuk Siklus I'!$B$13,"Mandiri",IF(J7>='Petunjuk Siklus I'!$B$14,"Kurang Mandiri","Belum Mandiri")))) -> Mandiri | L7: =IF(C7="","",IF(C7="Hadir",IF(COUNT(D7:H7)=5,"Lengkap","Belum Lengkap"),"Tidak Dianalisis")) -> Lengkap | O7: K4 | P7: Memeriksa kembali solusi yang dibuat.
A8: 4 | B8: X5-04 | C8: Hadir | D8: 4 | E8: 3 | F8: 2 | G8: 4 | H8: 4 | I8: =IF(AND(C8="Hadir",COUNT(D8:H8)=5),SUM(D8:H8),"") -> 17 | J8: =IF(I8="","",ROUND(I8/5,2)) -> 3.4 | K8: =IF(J8="","",IF(J8>='Petunjuk Siklus I'!$B$12,"Sangat Mandiri",IF(J8>='Petunjuk Siklus I'!$B$13,"Mandiri",IF(J8>='Petunjuk Siklus I'!$B$14,"Kurang Mandiri","Belum Mandiri")))) -> Mandiri | L8: =IF(C8="","",IF(C8="Hadir",IF(COUNT(D8:H8)=5,"Lengkap","Belum Lengkap"),"Tidak Dianalisis")) -> Lengkap | O8: K5 | P8: Memperbaiki solusi ketika menemukan kesalahan.
A9: 5 | B9: X5-05 | C9: Hadir | D9: 4 | E9: 3 | F9: 2 | G9: 3 | H9: 3 | I9: =IF(AND(C9="Hadir",COUNT(D9:H9)=5),SUM(D9:H9),"") -> 15 | J9: =IF(I9="","",ROUND(I9/5,2)) -> 3 | K9: =IF(J9="","",IF(J9>='Petunjuk Siklus I'!$B$12,"Sangat Mandiri",IF(J9>='Petunjuk Siklus I'!$B$13,"Mandiri",IF(J9>='Petunjuk Siklus I'!$B$14,"Kurang Mandiri","Belum Mandiri")))) -> Mandiri | L9: =IF(C9="","",IF(C9="Hadir",IF(COUNT(D9:H9)=5,"Lengkap","Belum Lengkap"),"Tidak Dianalisis")) -> Lengkap
A10: 6 | B10: X5-06 | C10: Hadir | D10: 4 | E10: 2 | F10: 2 | G10: 3 | H10: 3 | I10: =IF(AND(C10="Hadir",COUNT(D10:H10)=5),SUM(D10:H10),"") -> 14 | J10: =IF(I10="","",ROUND(I10/5,2)) -> 2.8 | K10: =IF(J10="","",IF(J10>='Petunjuk Siklus I'!$B$12,"Sangat Mandiri",IF(J10>='Petunjuk Siklus I'!$B$13,"Mandiri",IF(J10>='Petunjuk Siklus I'!$B$14,"Kurang Mandiri","Belum Mandiri")))) -> Mandiri | L10: =IF(C10="","",IF(C10="Hadir",IF(COUNT(D10:H10)=5,"Lengkap","Belum Lengkap"),"Tidak Dianalisis")) -> Lengkap
A11: 7 | B11: X5-07 | C11: Hadir | D11: 4 | E11: 2 | F11: 2 | G11: 4 | H11: 3 | I11: =IF(AND(C11="Hadir",COUNT(D11:H11)=5),SUM(D11:H11),"") -> 15 | J11: =IF(I11="","",ROUND(I11/5,2)) -> 3 | K11: =IF(J11="","",IF(J11>='Petunjuk Siklus I'!$B$12,"Sangat Mandiri",IF(J11>='Petunjuk Siklus I'!$B$13,"Mandiri",IF(J11>='Petunjuk Siklus I'!$B$14,"Kurang Mandiri","Belum Mandiri")))) -> Mandiri | L11: =IF(C11="","",IF(C11="Hadir",IF(COUNT(D11:H11)=5,"Lengkap","Belum Lengkap"),"Tidak Dianalisis")) -> Lengkap
A12: 8 | B12: X5-08 | C12: Hadir | D12: 4 | E12: 3 | F12: 2 | G12: 3 | H12: 4 | I12: =IF(AND(C12="Hadir",COUNT(D12:H12)=5),SUM(D12:H12),"") -> 16 | J12: =IF(I12="","",ROUND(I12/5,2)) -> 3.2 | K12: =IF(J12="","",IF(J12>='Petunjuk Siklus I'!$B$12,"Sangat Mandiri",IF(J12>='Petunjuk Siklus I'!$B$13,"Mandiri",IF(J12>='Petunjuk Siklus I'!$B$14,"Kurang Mandiri","Belum Mandiri")))) -> Mandiri | L12: =IF(C12="","",IF(C12="Hadir",IF(COUNT(D12:H12)=5,"Lengkap","Belum Lengkap"),"Tidak Dianalisis")) -> Lengkap
A13: 9 | B13: X5-09 | C13: Hadir | D13: 4 | E13: 3 | F13: 2 | G13: 3 | H13: 3 | I13: =IF(AND(C13="Hadir",COUNT(D13:H13)=5),SUM(D13:H13),"") -> 15 | J13: =IF(I13="","",ROUND(I13/5,2)) -> 3 | K13: =IF(J13="","",IF(J13>='Petunjuk Siklus I'!$B$12,"Sangat Mandiri",IF(J13>='Petunjuk Siklus I'!$B$13,"Mandiri",IF(J13>='Petunjuk Siklus I'!$B$14,"Kurang Mandiri","Belum Mandiri")))) -> Mandiri | L13: =IF(C13="","",IF(C13="Hadir",IF(COUNT(D13:H13)=5,"Lengkap","Belum Lengkap"),"Tidak Dianalisis")) -> Lengkap
A14: 10 | B14: X5-10 | C14: Hadir | D14: 4 | E14: 3 | F14: 2 | G14: 4 | H14: 3 | I14: =IF(AND(C14="Hadir",COUNT(D14:H14)=5),SUM(D14:H14),"") -> 16 | J14: =IF(I14="","",ROUND(I14/5,2)) -> 3.2 | K14: =IF(J14="","",IF(J14>='Petunjuk Siklus I'!$B$12,"Sangat Mandiri",IF(J14>='Petunjuk Siklus I'!$B$13,"Mandiri",IF(J14>='Petunjuk Siklus I'!$B$14,"Kurang Mandiri","Belum Mandiri")))) -> Mandiri | L14: =IF(C14="","",IF(C14="Hadir",IF(COUNT(D14:H14)=5,"Lengkap","Belum Lengkap"),"Tidak Dianalisis")) -> Lengkap
A15: 11 | B15: X5-11 | C15: Hadir | D15: 4 | E15: 3 | F15: 2 | G15: 3 | H15: 3 | I15: =IF(AND(C15="Hadir",COUNT(D15:H15)=5),SUM(D15:H15),"") -> 15 | J15: =IF(I15="","",ROUND(I15/5,2)) -> 3 | K15: =IF(J15="","",IF(J15>='Petunjuk Siklus I'!$B$12,"Sangat Mandiri",IF(J15>='Petunjuk Siklus I'!$B$13,"Mandiri",IF(J15>='Petunjuk Siklus I'!$B$14,"Kurang Mandiri","Belum Mandiri")))) -> Mandiri | L15: =IF(C15="","",IF(C15="Hadir",IF(COUNT(D15:H15)=5,"Lengkap","Belum Lengkap"),"Tidak Dianalisis")) -> Lengkap
A16: 12 | B16: X5-12 | C16: Hadir | D16: 4 | E16: 3 | F16: 2 | G16: 3 | H16: 4 | I16: =IF(AND(C16="Hadir",COUNT(D16:H16)=5),SUM(D16:H16),"") -> 16 | J16: =IF(I16="","",ROUND(I16/5,2)) -> 3.2 | K16: =IF(J16="","",IF(J16>='Petunjuk Siklus I'!$B$12,"Sangat Mandiri",IF(J16>='Petunjuk Siklus I'!$B$13,"Mandiri",IF(J16>='Petunjuk Siklus I'!$B$14,"Kurang Mandiri","Belum Mandiri")))) -> Mandiri | L16: =IF(C16="","",IF(C16="Hadir",IF(COUNT(D16:H16)=5,"Lengkap","Belum Lengkap"),"Tidak Dianalisis")) -> Lengkap
A17: 13 | B17: X5-13 | C17: Hadir | D17: 4 | E17: 3 | F17: 2 | G17: 4 | H17: 4 | I17: =IF(AND(C17="Hadir",COUNT(D17:H17)=5),SUM(D17:H17),"") -> 17 | J17: =IF(I17="","",ROUND(I17/5,2)) -> 3.4 | K17: =IF(J17="","",IF(J17>='Petunjuk Siklus I'!$B$12,"Sangat Mandiri",IF(J17>='Petunjuk Siklus I'!$B$13,"Mandiri",IF(J17>='Petunjuk Siklus I'!$B$14,"Kurang Mandiri","Belum Mandiri")))) -> Mandiri | L17: =IF(C17="","",IF(C17="Hadir",IF(COUNT(D17:H17)=5,"Lengkap","Belum Lengkap"),"Tidak Dianalisis")) -> Lengkap
A18: 14 | B18: X5-14 | C18: Hadir | D18: 4 | E18: 3 | F18: 2 | G18: 3 | H18: 3 | I18: =IF(AND(C18="Hadir",COUNT(D18:H18)=5),SUM(D18:H18),"") -> 15 | J18: =IF(I18="","",ROUND(I18/5,2)) -> 3 | K18: =IF(J18="","",IF(J18>='Petunjuk Siklus I'!$B$12,"Sangat Mandiri",IF(J18>='Petunjuk Siklus I'!$B$13,"Mandiri",IF(J18>='Petunjuk Siklus I'!$B$14,"Kurang Mandiri","Belum Mandiri")))) -> Mandiri | L18: =IF(C18="","",IF(C18="Hadir",IF(COUNT(D18:H18)=5,"Lengkap","Belum Lengkap"),"Tidak Dianalisis")) -> Lengkap
A19: 15 | B19: X5-15 | C19: Hadir | D19: 4 | E19: 3 | F19: 3 | G19: 4 | H19: 4 | I19: =IF(AND(C19="Hadir",COUNT(D19:H19)=5),SUM(D19:H19),"") -> 18 | J19: =IF(I19="","",ROUND(I19/5,2)) -> 3.6 | K19: =IF(J19="","",IF(J19>='Petunjuk Siklus I'!$B$12,"Sangat Mandiri",IF(J19>='Petunjuk Siklus I'!$B$13,"Mandiri",IF(J19>='Petunjuk Siklus I'!$B$14,"Kurang Mandiri","Belum Mandiri")))) -> Sangat Mandiri | L19: =IF(C19="","",IF(C19="Hadir",IF(COUNT(D19:H19)=5,"Lengkap","Belum Lengkap"),"Tidak Dianalisis")) -> Lengkap
A20: 16 | B20: X5-16 | C20: Hadir | D20: 4 | E20: 3 | F20: 2 | G20: 3 | H20: 3 | I20: =IF(AND(C20="Hadir",COUNT(D20:H20)=5),SUM(D20:H20),"") -> 15 | J20: =IF(I20="","",ROUND(I20/5,2)) -> 3 | K20: =IF(J20="","",IF(J20>='Petunjuk Siklus I'!$B$12,"Sangat Mandiri",IF(J20>='Petunjuk Siklus I'!$B$13,"Mandiri",IF(J20>='Petunjuk Siklus I'!$B$14,"Kurang Mandiri","Belum Mandiri")))) -> Mandiri | L20: =IF(C20="","",IF(C20="Hadir",IF(COUNT(D20:H20)=5,"Lengkap","Belum Lengkap"),"Tidak Dianalisis")) -> Lengkap
... A22: 18 | B22: X5-18 | C22: Hadir | D22: 4 | E22: 2 | F22: 2 | G22: 3 | H22: 3 | I22: =IF(AND(C22="Hadir",COUNT(D22:H22)=5),SUM(D22:H22),"") -> 14 | J22: =IF(I22="","",ROUND(I22/5,2)) -> 2.8 | K22: =IF(J22="","",IF(J22>='Petunjuk Siklus I'!$B$12,"Sangat Mandiri",IF(J22>='Petunjuk Siklus I'!$B$13,"Mandiri",IF(J22>='Petunjuk Siklus I'!$B$14,"Kurang Mandiri","Belum Mandiri")))) -> Mandiri | L22: =IF(C22="","",IF(C22="Hadir",IF(COUNT(D22:H22)=5,"Lengkap","Belum Lengkap"),"Tidak Dianalisis")) -> Lengkap
A23: 19 | B23: X5-19 | C23: Dispensasi | I23: =IF(AND(C23="Hadir",COUNT(D23:H23)=5),SUM(D23:H23),"") | J23: =IF(I23="","",ROUND(I23/5,2)) | K23: =IF(J23="","",IF(J23>='Petunjuk Siklus I'!$B$12,"Sangat Mandiri",IF(J23>='Petunjuk Siklus I'!$B$13,"Mandiri",IF(J23>='Petunjuk Siklus I'!$B$14,"Kurang Mandiri","Belum Mandiri")))) | L23: =IF(C23="","",IF(C23="Hadir",IF(COUNT(D23:H23)=5,"Lengkap","Belum Lengkap"),"Tidak Dianalisis")) -> Tidak Dianalisis
A24: 20 | B24: X5-20 | C24: Hadir | D24: 4 | E24: 4 | F24: 3 | G24: 4 | H24: 3 | I24: =IF(AND(C24="Hadir",COUNT(D24:H24)=5),SUM(D24:H24),"") -> 18 | J24: =IF(I24="","",ROUND(I24/5,2)) -> 3.6 | K24: =IF(J24="","",IF(J24>='Petunjuk Siklus I'!$B$12,"Sangat Mandiri",IF(J24>='Petunjuk Siklus I'!$B$13,"Mandiri",IF(J24>='Petunjuk Siklus I'!$B$14,"Kurang Mandiri","Belum Mandiri")))) -> Sangat Mandiri | L24: =IF(C24="","",IF(C24="Hadir",IF(COUNT(D24:H24)=5,"Lengkap","Belum Lengkap"),"Tidak Dianalisis")) -> Lengkap
A25: 21 | B25: X5-21 | C25: Hadir | D25: 4 | E25: 4 | F25: 4 | G25: 4 | H25: 4 | I25: =IF(AND(C25="Hadir",COUNT(D25:H25)=5),SUM(D25:H25),"") -> 20 | J25: =IF(I25="","",ROUND(I25/5,2)) -> 4 | K25: =IF(J25="","",IF(J25>='Petunjuk Siklus I'!$B$12,"Sangat Mandiri",IF(J25>='Petunjuk Siklus I'!$B$13,"Mandiri",IF(J25>='Petunjuk Siklus I'!$B$14,"Kurang Mandiri","Belum Mandiri")))) -> Sangat Mandiri | L25: =IF(C25="","",IF(C25="Hadir",IF(COUNT(D25:H25)=5,"Lengkap","Belum Lengkap"),"Tidak Dianalisis")) -> Lengkap
A26: 22 | B26: X5-22 | C26: Dispensasi | I26: =IF(AND(C26="Hadir",COUNT(D26:H26)=5),SUM(D26:H26),"") | J26: =IF(I26="","",ROUND(I26/5,2)) | K26: =IF(J26="","",IF(J26>='Petunjuk Siklus I'!$B$12,"Sangat Mandiri",IF(J26>='Petunjuk Siklus I'!$B$13,"Mandiri",IF(J26>='Petunjuk Siklus I'!$B$14,"Kurang Mandiri","Belum Mandiri")))) | L26: =IF(C26="","",IF(C26="Hadir",IF(COUNT(D26:H26)=5,"Lengkap","Belum Lengkap"),"Tidak Dianalisis")) -> Tidak Dianalisis
A27: 23 | B27: X5-23 | C27: Hadir | D27: 4 | E27: 3 | F27: 4 | G27: 3 | H27: 4 | I27: =IF(AND(C27="Hadir",COUNT(D27:H27)=5),SUM(D27:H27),"") -> 18 | J27: =IF(I27="","",ROUND(I27/5,2)) -> 3.6 | K27: =IF(J27="","",IF(J27>='Petunjuk Siklus I'!$B$12,"Sangat Mandiri",IF(J27>='Petunjuk Siklus I'!$B$13,"Mandiri",IF(J27>='Petunjuk Siklus I'!$B$14,"Kurang Mandiri","Belum Mandiri")))) -> Sangat Mandiri | L27: =IF(C27="","",IF(C27="Hadir",IF(COUNT(D27:H27)=5,"Lengkap","Belum Lengkap"),"Tidak Dianalisis")) -> Lengkap
A28: 24 | B28: X5-24 | C28: Hadir | D28: 4 | E28: 3 | F28: 2 | G28: 3 | H28: 3 | I28: =IF(AND(C28="Hadir",COUNT(D28:H28)=5),SUM(D28:H28),"") -> 15 | J28: =IF(I28="","",ROUND(I28/5,2)) -> 3 | K28: =IF(J28="","",IF(J28>='Petunjuk Siklus I'!$B$12,"Sangat Mandiri",IF(J28>='Petunjuk Siklus I'!$B$13,"Mandiri",IF(J28>='Petunjuk Siklus I'!$B$14,"Kurang Mandiri","Belum Mandiri")))) -> Mandiri | L28: =IF(C28="","",IF(C28="Hadir",IF(COUNT(D28:H28)=5,"Lengkap","Belum Lengkap"),"Tidak Dianalisis")) -> Lengkap
A29: 25 | B29: X5-25 | C29: Hadir | D29: 4 | E29: 4 | F29: 4 | G29: 4 | H29: 4 | I29: =IF(AND(C29="Hadir",COUNT(D29:H29)=5),SUM(D29:H29),"") -> 20 | J29: =IF(I29="","",ROUND(I29/5,2)) -> 4 | K29: =IF(J29="","",IF(J29>='Petunjuk Siklus I'!$B$12,"Sangat Mandiri",IF(J29>='Petunjuk Siklus I'!$B$13,"Mandiri",IF(J29>='Petunjuk Siklus I'!$B$14,"Kurang Mandiri","Belum Mandiri")))) -> Sangat Mandiri | L29: =IF(C29="","",IF(C29="Hadir",IF(COUNT(D29:H29)=5,"Lengkap","Belum Lengkap"),"Tidak Dianalisis")) -> Lengkap
A30: 26 | B30: X5-26 | C30: Hadir | D30: 4 | E30: 2 | F30: 2 | G30: 3 | H30: 3 | I30: =IF(AND(C30="Hadir",COUNT(D30:H30)=5),SUM(D30:H30),"") -> 14 | J30: =IF(I30="","",ROUND(I30/5,2)) -> 2.8 | K30: =IF(J30="","",IF(J30>='Petunjuk Siklus I'!$B$12,"Sangat Mandiri",IF(J30>='Petunjuk Siklus I'!$B$13,"Mandiri",IF(J30>='Petunjuk Siklus I'!$B$14,"Kurang Mandiri","Belum Mandiri")))) -> Mandiri | L30: =IF(C30="","",IF(C30="Hadir",IF(COUNT(D30:H30)=5,"Lengkap","Belum Lengkap"),"Tidak Dianalisis")) -> Lengkap
A31: 27 | B31: X5-27 | C31: Hadir | D31: 4 | E31: 2 | F31: 2 | G31: 3 | H31: 3 | I31: =IF(AND(C31="Hadir",COUNT(D31:H31)=5),SUM(D31:H31),"") -> 14 | J31: =IF(I31="","",ROUND(I31/5,2)) -> 2.8 | K31: =IF(J31="","",IF(J31>='Petunjuk Siklus I'!$B$12,"Sangat Mandiri",IF(J31>='Petunjuk Siklus I'!$B$13,"Mandiri",IF(J31>='Petunjuk Siklus I'!$B$14,"Kurang Mandiri","Belum Mandiri")))) -> Mandiri | L31: =IF(C31="","",IF(C31="Hadir",IF(COUNT(D31:H31)=5,"Lengkap","Belum Lengkap"),"Tidak Dianalisis")) -> Lengkap
A32: 28 | B32: X5-28 | C32: Hadir | D32: 4 | E32: 3 | F32: 2 | G32: 3 | H32: 3 | I32: =IF(AND(C32="Hadir",COUNT(D32:H32)=5),SUM(D32:H32),"") -> 15 | J32: =IF(I32="","",ROUND(I32/5,2)) -> 3 | K32: =IF(J32="","",IF(J32>='Petunjuk Siklus I'!$B$12,"Sangat Mandiri",IF(J32>='Petunjuk Siklus I'!$B$13,"Mandiri",IF(J32>='Petunjuk Siklus I'!$B$14,"Kurang Mandiri","Belum Mandiri")))) -> Mandiri | L32: =IF(C32="","",IF(C32="Hadir",IF(COUNT(D32:H32)=5,"Lengkap","Belum Lengkap"),"Tidak Dianalisis")) -> Lengkap
A33: 29 | B33: X5-29 | C33: Sakit | I33: =IF(AND(C33="Hadir",COUNT(D33:H33)=5),SUM(D33:H33),"") | J33: =IF(I33="","",ROUND(I33/5,2)) | K33: =IF(J33="","",IF(J33>='Petunjuk Siklus I'!$B$12,"Sangat Mandiri",IF(J33>='Petunjuk Siklus I'!$B$13,"Mandiri",IF(J33>='Petunjuk Siklus I'!$B$14,"Kurang Mandiri","Belum Mandiri")))) | L33: =IF(C33="","",IF(C33="Hadir",IF(COUNT(D33:H33)=5,"Lengkap","Belum Lengkap"),"Tidak Dianalisis")) -> Tidak Dianalisis
A34: 30 | B34: X5-30 | C34: Sakit | I34: =IF(AND(C34="Hadir",COUNT(D34:H34)=5),SUM(D34:H34),"") | J34: =IF(I34="","",ROUND(I34/5,2)) | K34: =IF(J34="","",IF(J34>='Petunjuk Siklus I'!$B$12,"Sangat Mandiri",IF(J34>='Petunjuk Siklus I'!$B$13,"Mandiri",IF(J34>='Petunjuk Siklus I'!$B$14,"Kurang Mandiri","Belum Mandiri")))) | L34: =IF(C34="","",IF(C34="Hadir",IF(COUNT(D34:H34)=5,"Lengkap","Belum Lengkap"),"Tidak Dianalisis")) -> Tidak Dianalisis
A35: 31 | B35: X5-31 | C35: Hadir | D35: 4 | E35: 3 | F35: 2 | G35: 3 | H35: 3 | I35: =IF(AND(C35="Hadir",COUNT(D35:H35)=5),SUM(D35:H35),"") -> 15 | J35: =IF(I35="","",ROUND(I35/5,2)) -> 3 | K35: =IF(J35="","",IF(J35>='Petunjuk Siklus I'!$B$12,"Sangat Mandiri",IF(J35>='Petunjuk Siklus I'!$B$13,"Mandiri",IF(J35>='Petunjuk Siklus I'!$B$14,"Kurang Mandiri","Belum Mandiri")))) -> Mandiri | L35: =IF(C35="","",IF(C35="Hadir",IF(COUNT(D35:H35)=5,"Lengkap","Belum Lengkap"),"Tidak Dianalisis")) -> Lengkap
A36: 32 | B36: X5-32 | C36: Hadir | D36: 4 | E36: 4 | F36: 4 | G36: 3 | H36: 4 | I36: =IF(AND(C36="Hadir",COUNT(D36:H36)=5),SUM(D36:H36),"") -> 19 | J36: =IF(I36="","",ROUND(I36/5,2)) -> 3.8 | K36: =IF(J36="","",IF(J36>='Petunjuk Siklus I'!$B$12,"Sangat Mandiri",IF(J36>='Petunjuk Siklus I'!$B$13,"Mandiri",IF(J36>='Petunjuk Siklus I'!$B$14,"Kurang Mandiri","Belum Mandiri")))) -> Sangat Mandiri | L36: =IF(C36="","",IF(C36="Hadir",IF(COUNT(D36:H36)=5,"Lengkap","Belum Lengkap"),"Tidak Dianalisis")) -> Lengkap
A37: 33 | B37: X5-33 | C37: Dispensasi | I37: =IF(AND(C37="Hadir",COUNT(D37:H37)=5),SUM(D37:H37),"") | J37: =IF(I37="","",ROUND(I37/5,2)) | K37: =IF(J37="","",IF(J37>='Petunjuk Siklus I'!$B$12,"Sangat Mandiri",IF(J37>='Petunjuk Siklus I'!$B$13,"Mandiri",IF(J37>='Petunjuk Siklus I'!$B$14,"Kurang Mandiri","Belum Mandiri")))) | L37: =IF(C37="","",IF(C37="Hadir",IF(COUNT(D37:H37)=5,"Lengkap","Belum Lengkap"),"Tidak Dianalisis")) -> Tidak Dianalisis
A38: 34 | B38: X5-34 | C38: Hadir | D38: 4 | E38: 3 | F38: 2 | G38: 4 | H38: 3 | I38: =IF(AND(C38="Hadir",COUNT(D38:H38)=5),SUM(D38:H38),"") -> 16 | J38: =IF(I38="","",ROUND(I38/5,2)) -> 3.2 | K38: =IF(J38="","",IF(J38>='Petunjuk Siklus I'!$B$12,"Sangat Mandiri",IF(J38>='Petunjuk Siklus I'!$B$13,"Mandiri",IF(J38>='Petunjuk Siklus I'!$B$14,"Kurang Mandiri","Belum Mandiri")))) -> Mandiri | L38: =IF(C38="","",IF(C38="Hadir",IF(COUNT(D38:H38)=5,"Lengkap","Belum Lengkap"),"Tidak Dianalisis")) -> Lengkap
A39: 35 | B39: X5-35 | C39: Hadir | D39: 4 | E39: 3 | F39: 4 | G39: 3 | H39: 4 | I39: =IF(AND(C39="Hadir",COUNT(D39:H39)=5),SUM(D39:H39),"") -> 18 | J39: =IF(I39="","",ROUND(I39/5,2)) -> 3.6 | K39: =IF(J39="","",IF(J39>='Petunjuk Siklus I'!$B$12,"Sangat Mandiri",IF(J39>='Petunjuk Siklus I'!$B$13,"Mandiri",IF(J39>='Petunjuk Siklus I'!$B$14,"Kurang Mandiri","Belum Mandiri")))) -> Sangat Mandiri | L39: =IF(C39="","",IF(C39="Hadir",IF(COUNT(D39:H39)=5,"Lengkap","Belum Lengkap"),"Tidak Dianalisis")) -> Lengkap
A40: 36 | B40: X5-36 | C40: Hadir | D40: 4 | E40: 3 | F40: 4 | G40: 3 | H40: 4 | I40: =IF(AND(C40="Hadir",COUNT(D40:H40)=5),SUM(D40:H40),"") -> 18 | J40: =IF(I40="","",ROUND(I40/5,2)) -> 3.6 | K40: =IF(J40="","",IF(J40>='Petunjuk Siklus I'!$B$12,"Sangat Mandiri",IF(J40>='Petunjuk Siklus I'!$B$13,"Mandiri",IF(J40>='Petunjuk Siklus I'!$B$14,"Kurang Mandiri","Belum Mandiri")))) -> Sangat Mandiri | L40: =IF(C40="","",IF(C40="Hadir",IF(COUNT(D40:H40)=5,"Lengkap","Belum Lengkap"),"Tidak Dianalisis")) -> Lengkap
A41: 37 | B41: X5-37 | C41: Hadir | D41: 4 | E41: 2 | F41: 2 | G41: 3 | H41: 3 | I41: =IF(AND(C41="Hadir",COUNT(D41:H41)=5),SUM(D41:H41),"") -> 14 | J41: =IF(I41="","",ROUND(I41/5,2)) -> 2.8 | K41: =IF(J41="","",IF(J41>='Petunjuk Siklus I'!$B$12,"Sangat Mandiri",IF(J41>='Petunjuk Siklus I'!$B$13,"Mandiri",IF(J41>='Petunjuk Siklus I'!$B$14,"Kurang Mandiri","Belum Mandiri")))) -> Mandiri | L41: =IF(C41="","",IF(C41="Hadir",IF(COUNT(D41:H41)=5,"Lengkap","Belum Lengkap"),"Tidak Dianalisis")) -> Lengkap
...

Sheet Refleksi Siklus I
A1: REKAP REFLEKSI PESERTA DIDIK — SIKLUS I (DATA PENDUKUNG)
A2: Masukkan skor 1–4 untuk delapan pernyataan refleksi. Kolom teks bersifat opsional untuk analisis kualitatif.
A4: No. | B4: Kode | C4: Kehadiran | D4: R1 | E4: R2 | F4: R3 | G4: R4 | H4: R5 | I4: R6 | J4: R7 | K4: R8 | L4: Rata-rata | M4: Lebih Berani? | N4: Paling Dipahami | O4: Paling Sulit | P4: Sebelum Minta Bantuan | Q4: Manfaat Kelompok | R4: Exit Ticket / Catatan
A5: 1 | B5: X5-01 | C5: Hadir | D5: 3 | E5: 3 | F5: 2 | G5: 3 | H5: 2 | I5: 2 | J5: 3 | K5: 3 | L5: =IF(AND(C5="Hadir",COUNT(D5:K5)=8),ROUND(AVERAGE(D5:K5),2),"") -> 2.63 | M5: Belum | N5: bagian algoritma narative | O5: flowchart dan pseudocode | P5: memeriksa kembali apakah saya salah membaca atau tidak | Q5: kami saling memberikan pendapat | R5: lebih terampil
A6: 2 | B6: X5-02 | C6: Hadir | D6: 3 | E6: 3 | F6: 3 | G6: 3 | H6: 3 | I6: 3 | J6: 3 | K6: 3 | L6: =IF(AND(C6="Hadir",COUNT(D6:K6)=8),ROUND(AVERAGE(D6:K6),2),"") -> 3 | M6: Ya | N6: penyusunan algoritma | O6: pseudocede | P6: meminta bantuan kpd teman yg lbh mengerti | Q6: karna bisa saling memberi jawaban dan bekerja sama | R6: lebih fokus dan tidak banyak bercanda atau ngobrol
A7: 3 | B7: X5-03 | C7: Hadir | D7: 2 | E7: 3 | F7: 2 | G7: 3 | H7: 2 | I7: 1 | J7: 3 | K7: 2 | L7: =IF(AND(C7="Hadir",COUNT(D7:K7)=8),ROUND(AVERAGE(D7:K7),2),"") -> 2.25 | M7: Ya | N7: Algoritma naratif | O7: Pseudocode dan FlowChart | P7: mencoba sendiri dulu | Q7: lebih mudah paham | R7: lebih fokus ketika guru menjelaskan
A8: 4 | B8: X5-04 | C8: Hadir | L8: =IF(AND(C8="Hadir",COUNT(D8:K8)=8),ROUND(AVERAGE(D8:K8),2),"")
A9: 5 | B9: X5-05 | C9: Hadir | D9: 4 | E9: 3 | F9: 4 | G9: 4 | H9: 4 | I9: 2 | J9: 4 | K9: 4 | L9: =IF(AND(C9="Hadir",COUNT(D9:K9)=8),ROUND(AVERAGE(D9:K9),2),"") -> 3.63 | M9: Ya | N9: Semua kecuali pseudocode | O9: Bagian pseudocode | P9: Mencari tahu sendiri lewat internet atau menanyakan kepada teman | Q9: Bisa Berdiskusi bersama lalu memecahkan masalah bersama² | R9: Lebih berlatih mengerjakan dan memahami soal
A10: 6 | B10: X5-06 | C10: Hadir | D10: 3 | E10: 3 | F10: 2 | G10: 2 | H10: 2 | I10: 3 | J10: 4 | K10: 3 | L10: =IF(AND(C10="Hadir",COUNT(D10:K10)=8),ROUND(AVERAGE(D10:K10),2),"") -> 2.75 | M10: Ya | N10: menyusun algoritma | O10: output | P10: berusaha | Q10: iya karena banyak pendapat | R10: lebih mempelajari semuanya
A11: 7 | B11: X5-07 | C11: Hadir | L11: =IF(AND(C11="Hadir",COUNT(D11:K11)=8),ROUND(AVERAGE(D11:K11),2),"")
A12: 8 | B12: X5-08 | C12: Hadir | D12: 1 | E12: 1 | F12: 2 | G12: 4 | H12: 4 | I12: 2 | J12: 2 | K12: 3 | L12: =IF(AND(C12="Hadir",COUNT(D12:K12)=8),ROUND(AVERAGE(D12:K12),2),"") -> 2.38 | M12: Ya | N12: Cara memecahkan tentang masalah | O12: Cara untuk menyelesaikanya/memecahkannya | P12: Prepare untuk nanya, atau nanya ke teman yang tahu | Q12: Lebih mudah untuk dikerjakan sesama dan bareng2 | R12: Semuanya saja ahahaha
A13: 9 | B13: X5-09 | C13: Hadir | D13: 3 | E13: 2 | F13: 3 | G13: 2 | H13: 3 | I13: 3 | J13: 4 | K13: 4 | L13: =IF(AND(C13="Hadir",COUNT(D13:K13)=8),ROUND(AVERAGE(D13:K13),2),"") -> 3 | M13: Ya | N13: Input-proses | O13: Diagram air, flowchart,pseudocode | P13: Baca ulang soalnya terus menerus sampai tau | Q13: Kamu bisa saling melengkapi informasi | R13: kalimat refleksi diri yang sering digunakan oleh pendidik (misalnya dalam Pengelolaan Kinerja PMM) atau siswa untuk mengevaluasi proses belajar.
A14: 10 | B14: X5-10 | C14: Hadir | D14: 2 | E14: 1 | F14: 3 | G14: 2 | H14: 3 | I14: 2 | J14: 3 | K14: 2 | L14: =IF(AND(C14="Hadir",COUNT(D14:K14)=8),ROUND(AVERAGE(D14:K14),2),"") -> 2.25 | M14: Belum | N14: Flowchart | O14: Flowchatr | P14: Meminta bantu ke teman | Q14: - | R14: Lebih bauk lagi dan fokuss
A15: 11 | B15: X5-11 | C15: Hadir | D15: 3 | E15: 3 | F15: 3 | G15: 3 | H15: 3 | I15: 3 | J15: 4 | K15: 3 | L15: =IF(AND(C15="Hadir",COUNT(D15:K15)=8),ROUND(AVERAGE(D15:K15),2),"") -> 3.13 | M15: Ya | N15: Menentukan input, proses, output dan membuat diagram alir, dan penyusun algoritma naratif | O15: pseudecode | P15: mencoba nya sendiri terlebih dahulu | Q15: iya karena kita jadi lebih memahami apa maksud dari masalah tersebut dan bisa menyelesaikan nya bersama sama | R15: mempelajari lagi materi psedecode
A16: 12 | B16: X5-12 | C16: Hadir | D16: 3 | E16: 3 | F16: 3 | G16: 2 | H16: 2 | I16: 2 | J16: 2 | K16: 3 | L16: =IF(AND(C16="Hadir",COUNT(D16:K16)=8),ROUND(AVERAGE(D16:K16),2),"") -> 2.5 | M16: Belum | N16: algoritma dan flowchart | O16: pseudocode | P16: bentanya pada teman | Q16: karena bagian yang susah jadi nudah | R16: bagaimana cara menyusun pseudocode
A17: 13 | B17: X5-13 | C17: Hadir | D17: 3 | E17: 3 | F17: 3 | G17: 2 | H17: 2 | I17: 3 | J17: 3 | K17: 3 | L17: =IF(AND(C17="Hadir",COUNT(D17:K17)=8),ROUND(AVERAGE(D17:K17),2),"") -> 2.75 | M17: Ya | N17: menganalisis soal | O17: susunan algoritma yang paling tepat | P17: mencoba mengerjakan nya sendiri | Q17: karena dapat menampung berbagai pendapat dan bisa mengajar kan teman yang belum mengerti, sama sama membantu | R17: lebih teliti lagi
A18: 14 | B18: X5-14 | C18: Hadir | D18: 3 | E18: 4 | F18: 4 | G18: 4 | H18: 3 | I18: 3 | J18: 3 | K18: 3 | L18: =IF(AND(C18="Hadir",COUNT(D18:K18)=8),ROUND(AVERAGE(D18:K18),2),"") -> 3.38 | M18: Ya | N18: flowchart | O18: pseudocode | P18: mencoba mengerjakan dulu sendiri. | Q18: dapat saling membantu. | R18: berlatih lagi pseudocode.
A19: 15 | B19: X5-15 | C19: Hadir | D19: 3 | E19: 3 | F19: 3 | G19: 3 | H19: 3 | I19: 3 | J19: 3 | K19: 3 | L19: =IF(AND(C19="Hadir",COUNT(D19:K19)=8),ROUND(AVERAGE(D19:K19),2),"") -> 3 | M19: Belum | N19: flowcard | O19: menghitung | P19: berusaha meminta bantuan | Q19: iya karna sangat memban | R19: lebih fokus lagi dan bisa lebih mengerti dan paham
A20: 16 | B20: X5-16 | C20: Hadir | D20: 1 | E20: 3 | F20: 3 | G20: 3 | H20: 2 | I20: 3 | J20: 3 | K20: 3 | L20: =IF(AND(C20="Hadir",COUNT(D20:K20)=8),ROUND(AVERAGE(D20:K20),2),"") -> 2.63 | M20: Ya | N20: Cara identifikasi input - proses - output | O20: Pseucode dan flowchart | P20: Berusaha menyelesaikan sendiri dan membuka buku catatan | Q20: Bisa mencari solusi bersama dan saling menyalurkan pendapat | R20: Akan belajar lebih baik dan memahami konsep dari seluruh materi
A21: 17 | B21: X5-17 | C21: Hadir | D21: 2 | E21: 3 | F21: 2 | G21: 2 | H21: 2 | I21: 2 | J21: 2 | K21: 2 | L21: =IF(AND(C21="Hadir",COUNT(D21:K21)=8),ROUND(AVERAGE(D21:K21),2),"") -> 2.13 | M21: Belum | N21: algoritma | O21: pseudocode | P21: bertanya kepada teman | Q21: menjadi tau isii masalah | R21: bisa lebih fokus dalam belajar
A22: 18 | B22: X5-18 | C22: Hadir | D22: 3 | E22: 2 | F22: 2 | G22: 3 | H22: 3 | I22: 2 | J22: 4 | K22: 1 | L22: =IF(AND(C22="Hadir",COUNT(D22:K22)=8),ROUND(AVERAGE(D22:K22),2),"") -> 2.5 | M22: Ya | N22: pseudo kode | O22: algoritma | P22: mencoba sendiri dan bertanya kepada detman | Q22: karena saya selalu belajr dengan teman saya | R22: cara membuat garis di flowchart
A23: 19 | B23: X5-19 | C23: Dispensasi | L23: =IF(AND(C23="Hadir",COUNT(D23:K23)=8),ROUND(AVERAGE(D23:K23),2),"")
A24: 20 | B24: X5-20 | C24: Hadir | D24: 3 | E24: 3 | F24: 2 | G24: 2 | H24: 2 | I24: 2 | J24: 3 | K24: 3 | L24: =IF(AND(C24="Hadir",COUNT(D24:K24)=8),ROUND(AVERAGE(D24:K24),2),"") -> 2.5 | M24: Belum | N24: flowcharc | O24: psudocode | P24: membuat psudocode sendiri lalu jika saya bingung saya menanyakann pada guru | Q24: karena lebih banyak yang membantu dan tidak merasa sendiri | R24: lebih bisa memahami psudocode
A25: 21 | B25: X5-21 | C25: Hadir | D25: 3 | E25: 3 | F25: 3 | G25: 3 | H25: 2 | I25: 2 | J25: 3 | K25: 4 | L25: =IF(AND(C25="Hadir",COUNT(D25:K25)=8),ROUND(AVERAGE(D25:K25),2),"") -> 2.88 | M25: Ya | N25: Membuat algoritma | O25: membuat pseudocode | P25: mencoba memecahkan masalahnya terlebih dahulu | Q25: karena bisa saling bertanya dan saling memberikan informasi dari satu sama lain | R25: menyusun pseudocode dan flowchart lebih baik dan berusaha sendiri
A26: 22 | B26: X5-22 | C26: Dispensasi | L26: =IF(AND(C26="Hadir",COUNT(D26:K26)=8),ROUND(AVERAGE(D26:K26),2),"")
A27: 23 | B27: X5-23 | C27: Hadir | D27: 3 | E27: 2 | F27: 3 | G27: 3 | H27: 3 | I27: 3 | J27: 3 | K27: 3 | L27: =IF(AND(C27="Hadir",COUNT(D27:K27)=8),ROUND(AVERAGE(D27:K27),2),"") -> 2.88 | M27: Ya | N27: Algoritma Naratif | O27: Pseudocode | P27: Menjawab semampunya terlebih dahulu | Q27: Logika kita tersatukan dan saling melengkapi | R27: Fokus saya dan logika saya
A28: 24 | B28: X5-24 | C28: Hadir | D28: 3 | E28: 4 | F28: 3 | G28: 3 | H28: 4 | I28: 3 | J28: 4 | K28: 4 | L28: =IF(AND(C28="Hadir",COUNT(D28:K28)=8),ROUND(AVERAGE(D28:K28),2),"") -> 3.5 | M28: Belum | N28: flowchart | O28: pseudocode | P28: mencoba dahulu | Q28: karena agar lebih mudah | R28: lebih fokus
A29: 25 | B29: X5-25 | C29: Hadir | L29: =IF(AND(C29="Hadir",COUNT(D29:K29)=8),ROUND(AVERAGE(D29:K29),2),"")
A30: 26 | B30: X5-26 | C30: Hadir | D30: 3 | E30: 2 | F30: 3 | G30: 2 | H30: 2 | I30: 3 | J30: 2 | K30: 1 | L30: =IF(AND(C30="Hadir",COUNT(D30:K30)=8),ROUND(AVERAGE(D30:K30),2),"") -> 2.25 | M30: Ya | N30: semuaa cuman beberapa adaa yang jurang paham | O30: bagian pseucode | P30: mencoba terlebih dahulu | Q30: mudah di kerjakan dan diskusi | R30: lebih perbanyak belajar sendiri
A31: 27 | B31: X5-27 | C31: Hadir | D31: 2 | E31: 3 | F31: 2 | G31: 2 | H31: 2 | I31: 2 | J31: 3 | K31: 3 | L31: =IF(AND(C31="Hadir",COUNT(D31:K31)=8),ROUND(AVERAGE(D31:K31),2),"") -> 2.38 | M31: Ya | N31: input,proses,output dan pseudocode | O31: . | P31: mencoba dulu | Q31: lebih mudah untuk memahami | R31: .
A32: 28 | B32: X5-28 | C32: Hadir | D32: 3 | E32: 3 | F32: 3 | G32: 3 | H32: 3 | I32: 2 | J32: 2 | K32: 4 | L32: =IF(AND(C32="Hadir",COUNT(D32:K32)=8),ROUND(AVERAGE(D32:K32),2),"") -> 2.88 | M32: Ya | N32: Input, proses, output, dan algoritma naratif | O32: Pseudocode | P32: Mencoba dulu sesuai kemampuan diri sendiri, coba bertanya kepada teman, lalu baru ke guru | Q32: Saya mengerjakan latihan soal untuk melatih dan mengetahui lebih banyak tentang algoritma | R32: Lebih banyak bertanya
A33: 29 | B33: X5-29 | C33: Sakit | L33: =IF(AND(C33="Hadir",COUNT(D33:K33)=8),ROUND(AVERAGE(D33:K33),2),"")
A34: 30 | B34: X5-30 | C34: Sakit | L34: =IF(AND(C34="Hadir",COUNT(D34:K34)=8),ROUND(AVERAGE(D34:K34),2),"")
