Workbook

Sheet SKL
A2: SILABUS PEMBELAJARAN
B4: Satuan Pendidikan | C4: MA Nurul Hidayah Padalarang
B5: Mata Pelajaran | C5: =PROPER(#REF!) -> #REF!
B6: Kelas/Semester | C6: =#REF!&" / "&#REF! -> #REF!
A8: KOMPETENSI INTI
A9: 1
A10: 2
A11: 3
A12: 4
A14: KOMPETENSI DASAR | C14: INDIKATOR | D14: TUJUAN PEMBELAJARAN | E14: MATERI POKOK | F14: MATERI PEMBELAJARAN | J14: ALOKASI WAKTU | K14: SUMBER BELAJAR
C15: =IF($B15="","","-") | D15: =IF($B15="","","-") | E15: =IF($B15="","","-") | F15: =IF($B15="","","-") | G15: =IF($B15="","","-") | H15: =IF($B15="","","-") | I15: =IF($B15="","","-") | J15: =IF($B15="","","-") | K15: =IF($B15="","","-")
C17: =IF($B17="","","-") | D17: =IF($B17="","","-") | E17: =IF($B17="","","-") | F17: =IF($B17="","","-") | G17: =IF($B17="","","-") | H17: =IF($B17="","","-") | I17: =IF($B17="","","-") | J17: =IF($B17="","","-") | K17: =IF($B17="","","-")
C19: =IF($B19="","","-") | D19: =IF($B19="","","-") | E19: =IF($B19="","","-") | F19: =IF($B19="","","-") | G19: =IF($B19="","","-") | H19: =IF($B19="","","-") | I19: =IF($B19="","","-") | J19: =IF($B19="","","-") | K19: =IF($B19="","","-")
C21: =IF($B21="","","-") | D21: =IF($B21="","","-") | E21: =IF($B21="","","-") | F21: =IF($B21="","","-") | G21: =IF($B21="","","-") | H21: =IF($B21="","","-") | I21: =IF($B21="","","-") | J21: =IF($B21="","","-") | K21: =IF($B21="","","-")
A23: KOMPETENSI DASAR | C23: INDIKATOR | D23: TUJUAN PEMBELAJARAN | E23: MATERI POKOK | F23: MATERI PEMBELAJARAN | J23: ALOKASI WAKTU | K23: SUMBER BELAJAR
C24: =IF($B24="","","-") | D24: =IF($B24="","","-") | E24: =IF($B24="","","-") | F24: =IF($B24="","","-") | G24: =IF($B24="","","-") | H24: =IF($B24="","","-") | I24: =IF($B24="","","-") | K24: =IF($B24="","","-")
C26: =IF($B26="","","-") | D26: =IF($B26="","","-") | E26: =IF($B26="","","-") | F26: =IF($B26="","","-") | G26: =IF($B26="","","-") | H26: =IF($B26="","","-") | I26: =IF($B26="","","-") | K26: =IF($B26="","","-")
C28: =IF($B28="","","-") | D28: =IF($B28="","","-") | E28: =IF($B28="","","-") | F28: =IF($B28="","","-") | G28: =IF($B28="","","-") | H28: =IF($B28="","","-") | I28: =IF($B28="","","-") | K28: =IF($B28="","","-")
K30: =IF(B30="","","Buku Paket Siswa Mata Pelajaran "&PROPER(MID($C$5,3,50))&" Kelas "&UPPER(MID($C$6,3,6)))
K38: =IF(B38="","","Buku Paket Siswa Mata Pelajaran "&PROPER(MID($C$5,3,50))&" Kelas "&UPPER(MID($C$6,3,6)))
K46: =IF(B46="","","Buku Paket Siswa Mata Pelajaran "&PROPER(MID($C$5,3,50))&" Kelas "&UPPER(MID($C$6,3,6)))
A54: KOMPETENSI DASAR | C54: INDIKATOR | D54: TUJUAN PEMBELAJARAN | E54: MATERI POKOK | F54: MATERI PEMBELAJARAN | J54: ALOKASI WAKTU | K54: SUMBER BELAJAR
K55: =IF(B55="","","Buku Paket Siswa Mata Pelajaran "&PROPER(MID($C$5,3,50))&" Kelas "&UPPER(MID($C$6,3,6)))
K63: =IF(B63="","","Buku Paket Siswa Mata Pelajaran "&PROPER(MID($C$5,3,50))&" Kelas "&UPPER(MID($C$6,3,6)))
K71: =IF(B71="","","Buku Paket Siswa Mata Pelajaran "&PROPER(MID($C$5,3,50))&" Kelas "&UPPER(MID($C$6,3,6)))
K79: =IF(B79="","","Buku Paket Siswa Mata Pelajaran "&PROPER(MID($C$5,3,50))&" Kelas "&UPPER(MID($C$6,3,6)))
B89: =#REF! -> #REF! | F89: ="Bandung Barat, Juli "&MID(#REF!,1,4) -> #REF!
B90: =#REF! -> #REF! | F90: =#REF! -> #REF!
B94: =#REF! -> #REF! | F94: =#REF! -> #REF!
B95: =#REF! -> #REF! | F95: =#REF! -> #REF!
A97: SILABUS PEMBELAJARAN
B99: Satuan Pendidikan | C99: =C4 -> MA Nurul Hidayah Padalarang
B100: Mata Pelajaran | C100: =C5 -> #REF!
B101: Kelas/Semester | C101: =C6 -> #REF!
A103: KOMPETENSI INTI
A104: 1
A105: 2
A106: 3
A107: 4
A109: KOMPETENSI DASAR | C109: INDIKATOR | D109: TUJUAN PEMBELAJARAN | E109: MATERI POKOK | F109: MATERI PEMBELAJARAN | J109: ALOKASI WAKTU | K109: SUMBER BELAJAR
...

Sheet KI-KD
A2: KOMPETENSI INTI DAN KOMPETENSI DASAR
A4: Satuan Pendidikan | C4: MA NURUL HIDAYAH PADALARANG
A5: Mata Pelajaran | C5: =#REF! -> #REF!
A6: Kelas/Semester | C6: 10 IPS / Semester Ganjil
A7: Tahun Pelajaran | C7: =#REF! -> #REF!
A9: NO | B9: KOMPETENSI INTI | D9: KOMPETENSI DASAR
A10: 1
A17: 2
A24: 3
A31: 4
B40: =#REF! -> #REF! | D40: ="Bandung Barat, Juli "&MID(#REF!,1,4) -> #REF!
B41: =#REF! -> #REF! | D41: =#REF! -> #REF!
B45: =#REF! -> #REF! | D45: =#REF! -> #REF!
B46: =#REF! -> #REF! | D46: =#REF! -> #REF!

Sheet Silabus
A2: SILABUS PEMBELAJARAN
B4: Satuan Pendidikan | C4: MA Nurul Hidayah Padalarang
B5: Mata Pelajaran | C5: =PROPER(#REF!) -> #REF!
B6: Kelas/Semester | C6: =#REF!&" / 1 (Ganjil)" -> #REF!
A8: KOMPETENSI INTI
A9: 1
A10: 2
A11: 3
A12: 4
A14: KOMPETENSI DASAR | C14: INDIKATOR | D14: TUJUAN PEMBELAJARAN | E14: MATERI POKOK | F14: MATERI PEMBELAJARAN | J14: ALOKASI WAKTU | K14: SUMBER BELAJAR
C15: =IF($B15="","","-") | D15: =IF($B15="","","-") | E15: =IF($B15="","","-") | F15: =IF($B15="","","-") | G15: =IF($B15="","","-") | H15: =IF($B15="","","-") | I15: =IF($B15="","","-") | J15: =IF($B15="","","-") | K15: =IF($B15="","","-")
C17: =IF($B17="","","-") | D17: =IF($B17="","","-") | E17: =IF($B17="","","-") | F17: =IF($B17="","","-") | G17: =IF($B17="","","-") | H17: =IF($B17="","","-") | I17: =IF($B17="","","-") | J17: =IF($B17="","","-") | K17: =IF($B17="","","-")
C19: =IF($B19="","","-") | D19: =IF($B19="","","-") | E19: =IF($B19="","","-") | F19: =IF($B19="","","-") | G19: =IF($B19="","","-") | H19: =IF($B19="","","-") | I19: =IF($B19="","","-") | J19: =IF($B19="","","-") | K19: =IF($B19="","","-")
C21: =IF($B21="","","-") | D21: =IF($B21="","","-") | E21: =IF($B21="","","-") | F21: =IF($B21="","","-") | G21: =IF($B21="","","-") | H21: =IF($B21="","","-") | I21: =IF($B21="","","-") | J21: =IF($B21="","","-") | K21: =IF($B21="","","-")
A23: KOMPETENSI DASAR | C23: INDIKATOR | D23: TUJUAN PEMBELAJARAN | E23: MATERI POKOK | F23: MATERI PEMBELAJARAN | J23: ALOKASI WAKTU | K23: SUMBER BELAJAR
C24: =IF($B24="","","-") | D24: =IF($B24="","","-") | E24: =IF($B24="","","-") | F24: =IF($B24="","","-") | G24: =IF($B24="","","-") | H24: =IF($B24="","","-") | I24: =IF($B24="","","-") | K24: =IF($B24="","","-")
C26: =IF($B26="","","-") | D26: =IF($B26="","","-") | E26: =IF($B26="","","-") | F26: =IF($B26="","","-") | G26: =IF($B26="","","-") | H26: =IF($B26="","","-") | I26: =IF($B26="","","-") | K26: =IF($B26="","","-")
C28: =IF($B28="","","-") | D28: =IF($B28="","","-") | E28: =IF($B28="","","-") | F28: =IF($B28="","","-") | G28: =IF($B28="","","-") | H28: =IF($B28="","","-") | I28: =IF($B28="","","-") | K28: =IF($B28="","","-")
K30: =IF(B30="","","Buku Paket Siswa Mata Pelajaran "&PROPER(MID($C$5,3,50))&" Kelas "&UPPER(MID($C$6,3,6)))
K38: =IF(B38="","","Buku Paket Siswa Mata Pelajaran "&PROPER(MID($C$5,3,50))&" Kelas "&UPPER(MID($C$6,3,6)))
K46: =IF(B46="","","Buku Paket Siswa Mata Pelajaran "&PROPER(MID($C$5,3,50))&" Kelas "&UPPER(MID($C$6,3,6)))
A54: KOMPETENSI DASAR | C54: INDIKATOR | D54: TUJUAN PEMBELAJARAN | E54: MATERI POKOK | F54: MATERI PEMBELAJARAN | J54: ALOKASI WAKTU | K54: SUMBER BELAJAR
K55: =IF(B55="","","Buku Paket Siswa Mata Pelajaran "&PROPER(MID($C$5,3,50))&" Kelas "&UPPER(MID($C$6,3,6)))
K63: =IF(B63="","","Buku Paket Siswa Mata Pelajaran "&PROPER(MID($C$5,3,50))&" Kelas "&UPPER(MID($C$6,3,6)))
K71: =IF(B71="","","Buku Paket Siswa Mata Pelajaran "&PROPER(MID($C$5,3,50))&" Kelas "&UPPER(MID($C$6,3,6)))
K79: =IF(B79="","","Buku Paket Siswa Mata Pelajaran "&PROPER(MID($C$5,3,50))&" Kelas "&UPPER(MID($C$6,3,6)))
B89: =#REF! -> #REF! | F89: ="Bandung Barat, Juli "&MID(#REF!,1,4) -> #REF!
B90: =#REF! -> #REF! | F90: =#REF! -> #REF!
B94: =#REF! -> #REF! | F94: =#REF! -> #REF!
B95: =#REF! -> #REF! | F95: =#REF! -> #REF!
A97: SILABUS PEMBELAJARAN
B99: Satuan Pendidikan | C99: =C4 -> MA Nurul Hidayah Padalarang
B100: Mata Pelajaran | C100: =C5 -> #REF!
B101: Kelas/Semester | C101: =#REF!&" / 2 (Genap)" -> #REF!
A103: KOMPETENSI INTI
A104: 1
A105: 2
A106: 3
A107: 4
A109: KOMPETENSI DASAR | C109: INDIKATOR | D109: TUJUAN PEMBELAJARAN | E109: MATERI POKOK | F109: MATERI PEMBELAJARAN | J109: ALOKASI WAKTU | K109: SUMBER BELAJAR
...

Sheet RPP
A2: RENCANA PELAKSANAAN PEMBELAJARAN (RPP)
A4: Satuan Pendidikan | C4: : | D4: MA NURUL HIDAYAH PADALARANG
A5: Mata Pelajaran | C5: : | D5: =#REF! -> #REF!
A6: Materi Pokok | C6: : | D6: =IF(Silabus!E30="","",Silabus!E30)
A7: Kelas/Semester | C7: : | D7: 10 IPS / Semester Ganjil
A8: Alokasi Waktu | C8: :
A10: A. KOMPETENSI INTI
A11: 1 | B11: =IF(Silabus!B9="","",Silabus!B9)
A12: 2 | B12: =IF(Silabus!B10="","",Silabus!B10)
A13: 3 | B13: =IF(Silabus!B11="","",Silabus!B11)
A14: 4 | B14: =IF(Silabus!B12="","",Silabus!B12)
A16: B. KOMPETENSI DASAR
A20: C. INDIKATOR PENCAPAIAN
A21: =IF(B21="","","v") | B21: =IF(Silabus!C30="","",Silabus!C30)
A22: =IF(B22="","","v") | B22: =IF(Silabus!C32="","",Silabus!C32)
A23: =IF(B23="","","v") | B23: =IF(Silabus!C34="","",Silabus!C34)
A24: =IF(B24="","","v") | B24: =IF(Silabus!C36="","",Silabus!C36)
A26: D. TUJUAN PEMBELAJARAN
A27: =IF(B27="","","v") | B27: =IF(Silabus!D30="","",Silabus!D30)
A28: =IF(B28="","","v") | B28: =IF(Silabus!D32="","",Silabus!D32)
A29: =IF(B29="","","v") | B29: =IF(Silabus!D34="","",Silabus!D34)
A30: =IF(B30="","","v") | B30: =IF(Silabus!D36="","",Silabus!D36)
A32: E. MATERI PEMBELAJARAN
A33: =IF(B33="","","v") | B33: =IF(Silabus!F30="","",Silabus!F30)
A34: =IF(B34="","","v") | B34: =IF(Silabus!F31="","",Silabus!F31)
A35: =IF(B35="","","v") | B35: =IF(Silabus!F32="","",Silabus!F32)
A36: =IF(B36="","","v") | B36: =IF(Silabus!F33="","",Silabus!F33)
A37: =IF(B37="","","v") | B37: =IF(Silabus!F34="","",Silabus!F34)
A38: =IF(B38="","","v") | B38: =IF(Silabus!F35="","",Silabus!F35)
A39: =IF(B39="","","v") | B39: =IF(Silabus!F36="","",Silabus!F36)
A40: =IF(B40="","","v") | B40: =IF(Silabus!F37="","",Silabus!F37)
A42: F. METODE PEMBELAJARAN
A43: =IF(B43="","","v") -> v | B43: Ceramah
A44: =IF(B44="","","v") -> v | B44: Diskusi
A45: =IF(B45="","","v")
A46: =IF(B46="","","v")
A48: G. MEDIA PEMBELAJARAN
A49: =IF(B49="","","v") | B49: =IF($D$6="","","Buku Paket Siswa Mata Pelajaran Al-Quran Hadits kelas "&MID(D7,1,6))
A50: =IF(B50="","","v")
A51: =IF(B51="","","v")
...

Sheet KKM
A2: KRITERIA KETUNTASAN MINIMAL (KKM)
A3: =#REF! -> #REF!
A4: =#REF! -> #REF!
A5: ='Program Tahunan'!A5:D5 -> #REF!
A6: =#REF! -> #REF!
A9: SEMESTER 1
A10: NO | B10: KOMPETENSI DASAR | C10: KOMPLEKSITAS | D10: INTAKE | E10: DAYA DUKUNG | F10: KKM PER KD
F11: =IFERROR(IF(B11=0,"",AVERAGE(C11:E11)),"")
F12: =IFERROR(IF(B12=0,"",AVERAGE(C12:E12)),"")
F13: =IFERROR(IF(B13=0,"",AVERAGE(C13:E13)),"")
F14: =IFERROR(IF(B14=0,"",AVERAGE(C14:E14)),"")
F15: =IFERROR(IF(B15=0,"",AVERAGE(C15:E15)),"")
F16: =IFERROR(IF(B16=0,"",AVERAGE(C16:E16)),"")
F17: =IFERROR(IF(B17=0,"",AVERAGE(C17:E17)),"")
F18: =IFERROR(IF(B18=0,"",AVERAGE(C18:E18)),"")
F19: =IFERROR(IF(B19=0,"",AVERAGE(C19:E19)),"")
F20: =IFERROR(IF(B20=0,"",AVERAGE(C20:E20)),"")
F21: =IFERROR(IF(B21=0,"",AVERAGE(C21:E21)),"")
F22: =IFERROR(IF(B22=0,"",AVERAGE(C22:E22)),"")
... F24: =IFERROR(IF(B24=0,"",AVERAGE(C24:E24)),"")
A25: JUMLAH | F25: =IFERROR(AVERAGE(F11:F24),0) -> 0
B28: =#REF! -> #REF! | D28: ="Bandung Barat, Juli "&MID(#REF!,1,4) -> #REF!
B29: =#REF! -> #REF! | D29: =#REF! -> #REF!
B33: =#REF! -> #REF! | D33: =#REF! -> #REF!
B34: =#REF! -> #REF! | D34: =#REF! -> #REF!
A36: =A2 -> KRITERIA KETUNTASAN MINIMAL (KKM)
A37: =A3 -> #REF!
A38: =A4 -> #REF!
A39: =A5 -> #REF!
A40: =A6 -> #REF!
A43: SEMESTER 2
A44: NO | B44: KOMPETENSI DASAR | C44: KOMPLEKSITAS | D44: INTAKE | E44: DAYA DUKUNG | F44: KKM PER KD
F45: =IFERROR(IF(B45=0,"",AVERAGE(C45:E45)),"")
F46: =IFERROR(IF(B46=0,"",AVERAGE(C46:E46)),"")
F47: =IFERROR(IF(B47=0,"",AVERAGE(C47:E47)),"")
F48: =IFERROR(IF(B48=0,"",AVERAGE(C48:E48)),"")
F49: =IFERROR(IF(B49=0,"",AVERAGE(C49:E49)),"")
F50: =IFERROR(IF(B50=0,"",AVERAGE(C50:E50)),"")
F51: =IFERROR(IF(B51=0,"",AVERAGE(C51:E51)),"")
F52: =IFERROR(IF(B52=0,"",AVERAGE(C52:E52)),"")
...

Sheet Program Tahunan
A2: PROGRAM TAHUNAN
A3: =#REF! -> #REF!
A4: =#REF! -> #REF!
A5: ="KELAS "&#REF! -> #REF!
A6: =#REF! -> #REF!
A8: SEMESTER 1
A9: NO | B9: KOMPETENSI DASAR | D9: ALOKASI WAKTU
A10: =IF(KKM!A11="","",KKM!A11) | B10: =IF(KKM!B11="","",KKM!B11) | C10: =IF(KKM!C11="","",KKM!C11)
A11: =IF(KKM!A12="","",KKM!A12) | B11: =IF(KKM!B12="","",KKM!B12) | C11: =IF(KKM!C12="","",KKM!C12)
A12: =IF(KKM!A13="","",KKM!A13) | B12: =IF(KKM!B13="","",KKM!B13) | C12: =IF(KKM!C13="","",KKM!C13)
A13: =IF(KKM!A14="","",KKM!A14) | B13: =IF(KKM!B14="","",KKM!B14) | C13: =IF(KKM!C14="","",KKM!C14)
A14: =IF(KKM!A15="","",KKM!A15) | B14: =IF(KKM!B15="","",KKM!B15) | C14: =IF(KKM!C15="","",KKM!C15)
A15: =IF(KKM!A16="","",KKM!A16) | B15: =IF(KKM!B16="","",KKM!B16) | C15: =IF(KKM!C16="","",KKM!C16)
A16: =IF(KKM!A17="","",KKM!A17) | B16: =IF(KKM!B17="","",KKM!B17) | C16: =IF(KKM!C17="","",KKM!C17)
A17: =IF(KKM!A18="","",KKM!A18) | B17: =IF(KKM!B18="","",KKM!B18) | C17: =IF(KKM!C18="","",KKM!C18)
A18: =IF(KKM!A19="","",KKM!A19) | B18: =IF(KKM!B19="","",KKM!B19) | C18: =IF(KKM!C19="","",KKM!C19)
A19: =IF(KKM!A20="","",KKM!A20) | B19: =IF(KKM!B20="","",KKM!B20) | C19: =IF(KKM!C20="","",KKM!C20)
A20: =IF(KKM!A21="","",KKM!A21) | B20: =IF(KKM!B21="","",KKM!B21) | C20: =IF(KKM!C21="","",KKM!C21)
A21: =IF(KKM!A22="","",KKM!A22) | B21: =IF(KKM!B22="","",KKM!B22) | C21: =IF(KKM!C22="","",KKM!C22)
... A23: =IF(KKM!A24="","",KKM!A24) | B23: =IF(KKM!B24="","",KKM!B24) | C23: =IF(KKM!C24="","",KKM!C24)
A24: JUMLAH | D24: =SUM(D10:D23)&" JP"&" (x "&#REF!&" Menit)" -> #REF!
A26: SEMESTER 2
A27: NO | B27: KOMPETENSI DASAR | D27: ALOKASI WAKTU
A28: =IF(KKM!A45="","",KKM!A45) | B28: =IF(KKM!B45="","",KKM!B45) | C28: =IF(KKM!C45="","",KKM!C45)
A29: =IF(KKM!A46="","",KKM!A46) | B29: =IF(KKM!B46="","",KKM!B46) | C29: =IF(KKM!C46="","",KKM!C46)
A30: =IF(KKM!A47="","",KKM!A47) | B30: =IF(KKM!B47="","",KKM!B47) | C30: =IF(KKM!C47="","",KKM!C47)
A31: =IF(KKM!A48="","",KKM!A48) | B31: =IF(KKM!B48="","",KKM!B48) | C31: =IF(KKM!C48="","",KKM!C48)
A32: =IF(KKM!A49="","",KKM!A49) | B32: =IF(KKM!B49="","",KKM!B49) | C32: =IF(KKM!C49="","",KKM!C49)
A33: =IF(KKM!A50="","",KKM!A50) | B33: =IF(KKM!B50="","",KKM!B50) | C33: =IF(KKM!C50="","",KKM!C50)
A34: =IF(KKM!A51="","",KKM!A51) | B34: =IF(KKM!B51="","",KKM!B51) | C34: =IF(KKM!C51="","",KKM!C51)
A35: =IF(KKM!A52="","",KKM!A52) | B35: =IF(KKM!B52="","",KKM!B52) | C35: =IF(KKM!C52="","",KKM!C52)
A36: =IF(KKM!A53="","",KKM!A53) | B36: =IF(KKM!B53="","",KKM!B53) | C36: =IF(KKM!C53="","",KKM!C53)
A37: =IF(KKM!A54="","",KKM!A54) | B37: =IF(KKM!B54="","",KKM!B54) | C37: =IF(KKM!C54="","",KKM!C54)
A38: =IF(KKM!A55="","",KKM!A55) | B38: =IF(KKM!B55="","",KKM!B55) | C38: =IF(KKM!C55="","",KKM!C55)
A39: =IF(KKM!A56="","",KKM!A56) | B39: =IF(KKM!B56="","",KKM!B56) | C39: =IF(KKM!C56="","",KKM!C56)
... A41: =IF(KKM!A58="","",KKM!A58) | B41: =IF(KKM!B58="","",KKM!B58) | C41: =IF(KKM!C58="","",KKM!C58)
A42: JUMLAH | D42: =SUM(D28:D41)&" JP"&" (x "&#REF!&" Menit)" -> #REF!
B45: =#REF! -> #REF! | C45: ="Bandung Barat, Juli "&MID(#REF!,1,4) -> #REF!
B46: =#REF! -> #REF! | C46: =#REF! -> #REF!
B50: =#REF! -> #REF! | C50: =#REF! -> #REF!
...

Sheet Program Semester
A2: PROGRAM SEMESTER
A3: ='Program Tahunan'!$A$3:$D$3 -> #REF!
A4: ='Program Tahunan'!A4:$D$4 -> #REF!
A5: ='Program Tahunan'!A5:$D$5 -> #REF!
A6: ='Program Tahunan'!A6:$D$6 -> #REF!
A9: SEMESTER 1 (GANJIL)
A10: NO | B10: KOMPETENSI DASAR | C10: ALOKASI WAKTU | D10: JULI | I10: AGUSTUS | N10: SEPTEMBER | S10: OKTOBER | X10: NOPEMBER | AC10: DESEMBER | AH10: KETERANGAN
D11: 1 | E11: 2 | F11: 3 | G11: 4 | H11: 5 | I11: 1 | J11: 2 | K11: 3 | L11: 4 | M11: 5 | N11: 1 | O11: 2 | P11: 3 | Q11: 4 | R11: 5 | S11: 1 | T11: 2 | U11: 3 | V11: 4 | W11: 5 | X11: 1 | Y11: 2 | Z11: 3 | AA11: 4 | AB11: 5 | AC11: 1 | AD11: 2 | AE11: 3 | AF11: 4 | AG11: 5
A12: =IF('Program Tahunan'!A10="","",'Program Tahunan'!A10) | B12: =IF('Program Tahunan'!B10="","",'Program Tahunan'!B10) | C12: =IF('Program Tahunan'!D10="","",'Program Tahunan'!D10) | H12: P | I12: P | AH12: =IF(B12="","",COUNTIF(D12:AG12,"P")&" JP")
A13: =IF('Program Tahunan'!A11="","",'Program Tahunan'!A11) | B13: =IF('Program Tahunan'!B11="","",'Program Tahunan'!B11) | C13: =IF('Program Tahunan'!D11="","",'Program Tahunan'!D11) | AH13: =IF(B13="","",COUNTIF(D13:AG13,"P")&" JP")
A14: =IF('Program Tahunan'!A12="","",'Program Tahunan'!A12) | B14: =IF('Program Tahunan'!B12="","",'Program Tahunan'!B12) | C14: =IF('Program Tahunan'!D12="","",'Program Tahunan'!D12) | AH14: =IF(B14="","",COUNTIF(D14:AG14,"P")&" JP")
A15: =IF('Program Tahunan'!A13="","",'Program Tahunan'!A13) | B15: =IF('Program Tahunan'!B13="","",'Program Tahunan'!B13) | C15: =IF('Program Tahunan'!D13="","",'Program Tahunan'!D13) | AH15: =IF(B15="","",COUNTIF(D15:AG15,"P")&" JP")
A16: =IF('Program Tahunan'!A14="","",'Program Tahunan'!A14) | B16: =IF('Program Tahunan'!B14="","",'Program Tahunan'!B14) | C16: =IF('Program Tahunan'!D14="","",'Program Tahunan'!D14) | AH16: =IF(B16="","",COUNTIF(D16:AG16,"P")&" JP")
A17: =IF('Program Tahunan'!A15="","",'Program Tahunan'!A15) | B17: =IF('Program Tahunan'!B15="","",'Program Tahunan'!B15) | C17: =IF('Program Tahunan'!D15="","",'Program Tahunan'!D15) | AH17: =IF(B17="","",COUNTIF(D17:AG17,"P")&" JP")
A18: =IF('Program Tahunan'!A16="","",'Program Tahunan'!A16) | B18: =IF('Program Tahunan'!B16="","",'Program Tahunan'!B16) | C18: =IF('Program Tahunan'!D16="","",'Program Tahunan'!D16) | AH18: =IF(B18="","",COUNTIF(D18:AG18,"P")&" JP")
A19: =IF('Program Tahunan'!A17="","",'Program Tahunan'!A17) | B19: =IF('Program Tahunan'!B17="","",'Program Tahunan'!B17) | C19: =IF('Program Tahunan'!D17="","",'Program Tahunan'!D17) | AH19: =IF(B19="","",COUNTIF(D19:AG19,"P")&" JP")
A20: =IF('Program Tahunan'!A18="","",'Program Tahunan'!A18) | B20: =IF('Program Tahunan'!B18="","",'Program Tahunan'!B18) | C20: =IF('Program Tahunan'!D18="","",'Program Tahunan'!D18) | AH20: =IF(B20="","",COUNTIF(D20:AG20,"P")&" JP")
A21: =IF('Program Tahunan'!A19="","",'Program Tahunan'!A19) | B21: =IF('Program Tahunan'!B19="","",'Program Tahunan'!B19) | C21: =IF('Program Tahunan'!D19="","",'Program Tahunan'!D19) | AH21: =IF(B21="","",COUNTIF(D21:AG21,"P")&" JP")
A22: =IF('Program Tahunan'!A20="","",'Program Tahunan'!A20) | B22: =IF('Program Tahunan'!B20="","",'Program Tahunan'!B20) | C22: =IF('Program Tahunan'!D20="","",'Program Tahunan'!D20) | AH22: =IF(B22="","",COUNTIF(D22:AG22,"P")&" JP")
A23: =IF('Program Tahunan'!A21="","",'Program Tahunan'!A21) | B23: =IF('Program Tahunan'!B21="","",'Program Tahunan'!B21) | C23: =IF('Program Tahunan'!D21="","",'Program Tahunan'!D21) | AH23: =IF(B23="","",COUNTIF(D23:AG23,"P")&" JP")
A24: =IF('Program Tahunan'!A22="","",'Program Tahunan'!A22) | B24: =IF('Program Tahunan'!B22="","",'Program Tahunan'!B22) | C24: =IF('Program Tahunan'!D22="","",'Program Tahunan'!D22) | AH24: =IF(B24="","",COUNTIF(D24:AG24,"P")&" JP")
A25: =IF('Program Tahunan'!A23="","",'Program Tahunan'!A23) | B25: =IF('Program Tahunan'!B23="","",'Program Tahunan'!B23) | C25: =IF('Program Tahunan'!D23="","",'Program Tahunan'!D23) | AH25: =IF(B25="","",COUNTIF(D25:AG25,"P")&" JP")
B28: =#REF! -> #REF! | Y28: ="Bandung Barat, Juli "&MID(#REF!,1,4) -> #REF!
B29: =#REF! -> #REF! | Y29: =#REF! -> #REF!
B33: =#REF! -> #REF! | Y33: =#REF! -> #REF!
B34: =#REF! -> #REF! | Y34: =#REF! -> #REF!
A35: PROGRAM SEMESTER
A36: MA NURUL HIDAYAH PADALARANG
A37: KABUPATEN BANDUNG BARAT
A38: KELAS 10 IPS
A39: TAHUN PELAJARAN 2022/2023
A42: SEMESTER 2 (GENAP)
A43: NO | B43: KOMPETENSI DASAR | C43: ALOKASI WAKTU | D43: JANUARI | I43: FEBRUARI | N43: MARET | S43: APRIL | X43: MEI | AC43: JUNI | AH43: KETERANGAN
D44: 1 | E44: 2 | F44: 3 | G44: 4 | H44: 5 | I44: 1 | J44: 2 | K44: 3 | L44: 4 | M44: 5 | N44: 1 | O44: 2 | P44: 3 | Q44: 4 | R44: 5 | S44: 1 | T44: 2 | U44: 3 | V44: 4 | W44: 5 | X44: 1 | Y44: 2 | Z44: 3 | AA44: 4 | AB44: 5 | AC44: 1 | AD44: 2 | AE44: 3 | AF44: 4 | AG44: 5
A45: =IF('Program Tahunan'!A28="","",'Program Tahunan'!A28) | B45: =IF('Program Tahunan'!B28="","",'Program Tahunan'!B28) | C45: ='Program Tahunan'!D28 -> 0 | AH45: =IF(B45="","",COUNTIF(D45:AG45,"P")&" JP")
A46: =IF('Program Tahunan'!A29="","",'Program Tahunan'!A29) | B46: =IF('Program Tahunan'!B29="","",'Program Tahunan'!B29) | C46: ='Program Tahunan'!D29 -> 0 | AH46: =IF(B46="","",COUNTIF(D46:AG46,"P")&" JP")
A47: =IF('Program Tahunan'!A30="","",'Program Tahunan'!A30) | B47: =IF('Program Tahunan'!B30="","",'Program Tahunan'!B30) | C47: ='Program Tahunan'!D30 -> 0 | AH47: =IF(B47="","",COUNTIF(D47:AG47,"P")&" JP")
A48: =IF('Program Tahunan'!A31="","",'Program Tahunan'!A31) | B48: =IF('Program Tahunan'!B31="","",'Program Tahunan'!B31) | C48: ='Program Tahunan'!D31 -> 0 | AH48: =IF(B48="","",COUNTIF(D48:AG48,"P")&" JP")
A49: =IF('Program Tahunan'!A32="","",'Program Tahunan'!A32) | B49: =IF('Program Tahunan'!B32="","",'Program Tahunan'!B32) | C49: ='Program Tahunan'!D32 -> 0 | AH49: =IF(B49="","",COUNTIF(D49:AG49,"P")&" JP")
A50: =IF('Program Tahunan'!A33="","",'Program Tahunan'!A33) | B50: =IF('Program Tahunan'!B33="","",'Program Tahunan'!B33) | C50: ='Program Tahunan'!D33 -> 0 | AH50: =IF(B50="","",COUNTIF(D50:AG50,"P")&" JP")
...

Sheet CV
A2: ADMINISTRASI GURU
A3: SMA NEGERI 15 KOTA BANDUNG
A4: TAHUN AJARAN 2026/2027
G12: BUKU KERJA 1 : - Analisis SKL - KI & KD - Silabus - RPP - KKM | I12: BUKU KERJA 2 : - Kode Etik Guru - Ikrar Guru - Tata Tertib Guru - Pembiasaan Guru - Kalender Pendidikan - Alokasi Waktu - Program Tahunan - Program Semester - Jurnal Agenda Guru | K12: BUKU KERJA 3 : - Daftar Hadir Siswa - Penilaian Sikap Spiritual & Sosial - Penilaian Pengetahuan & Keterampilan - Analisis PTS - Analisis PAS / PAT - Jadwal Mengajar - Daya Serap Siswa | M12: BUKU KERJA 4 : - Evaluasi Diri Guru - Rencana Tindak Lanjut
A21: Nama Guru :
A22: AHMAD NURSYIFA | B22: ANDI DWI IRFANDI | C22: ANDI DWI IRFANDI | D22: ANDI DWI IRFANDI | E22: ANDI DWI IRFANDI
A23: NIP. - | B23: NIP. - | C23: NIP. - | D23: NIP. - | E23: NIP. -
A26: Mata Pelajaran :
A27: INFORMATIKA
A30: PEMERINTAH DAERAH PROVINSI JAWA BARAT
A31: DINAS PENDIDIKAN
A32: CABANG DINAS PENDIDIKAN WILAYAH VII
A33: 2026

Sheet Jurnal 10-5
A1: =CV!A3 -> SMA NEGERI 15 KOTA BANDUNG
A2: KABUPATEN BANDUNG BARAT
A3: =CV!A4 -> TAHUN AJARAN 2026/2027
A5: JURNAL AGENDA GURU
B6: ="Mata Pelajaran : "&CV!A27 -> Mata Pelajaran : INFORMATIKA | G6: Kelas : 10-5
A8: No | B8: Tanggal | C8: Jam Ke | D8: KD / Materi / Kegiatan | E8: Jumlah Siswa | G8: Catatan Guru | H8: Paraf
E9: Hadir | F9: Tidak Hadir
A10: 1 | B10: 46261 | D10: Perkenalan dan Pengantar Materi | E10: 41 | F10: 5
A11: =A10+1 -> 2 | B11: 46282 | D11: PTS | E11: 45 | F11: 1
A12: =A11+1 -> 3 | B12: 46289 | D12: Algortima Naratif dan Flowchart | E12: 46 | F12: 0
A13: =A12+1 -> 4 | B13: 46296 | D13: Review Algoritma Naratif dan Flowchart, Variabel dan Tipe Data, Pseudocode | E13: 42 | F13: 2
A14: =A13+1 -> 5 | B14: 46303 | D14: Latihan Algoritma Naratif, Flowchart, dan Pseudocode | E14: 43 | F14: 3
A15: =A14+1 -> 6 | B15: 46310 | D15: PTK
A16: =A15+1 -> 7
A17: =A16+1 -> 8
A18: =A17+1 -> 9
A19: =A18+1 -> 10
A20: =A19+1 -> 11
A21: =A20+1 -> 12
A22: =A21+1 -> 13
A23: =A22+1 -> 14
A24: =A23+1 -> 15
A25: =A24+1 -> 16
A26: =A25+1 -> 17
A27: =A26+1 -> 18
... A104: =A103+1 -> 95
B105: =TODAY() -> 46311
B106: Mengetahui, | F106: Bandung, Oktober 2026
B107: Wali Kelas | F107: Guru Mata Pelajaran
B111: Moch. Maulana Hidayat, S.Pd. | F111: AHMAD NURSYIFA, S.Kom.
B112: NIP. 199011162024211011 | F112: NIP. -

Sheet Absensi 10-5
A1: DAFTAR HADIR SISWA | AN1: =A1 -> DAFTAR HADIR SISWA
A2: =CV!A3 -> SMA NEGERI 15 KOTA BANDUNG | AN2: =A2 -> SMA NEGERI 15 KOTA BANDUNG
A3: =#REF! -> #REF! | AN3: =CV!A4 -> TAHUN AJARAN 2026/2027
B6: Kelas | C6: 11-5 | AH6: Semester | AI6: 2 (Genap) | AO6: Kelas | AP6: 10-5 | BU6: Semester | BV6: 1 (Ganjil)
A8: No | B8: Nama | C8: JK | D8: Tanggal | AH8: Jumlah Hadir | AI8: Jumlah Ketidak Hadiran | AN8: =CONCATENATE(A8) -> No | AO8: =CONCATENATE(B8) -> Nama | AP8: =CONCATENATE(C8) -> JK | AQ8: =CONCATENATE(D8) -> Tanggal | AR8: =CONCATENATE(E8) | AS8: =CONCATENATE(F8) | AT8: =CONCATENATE(G8) | AU8: =CONCATENATE(H8) | ... BY8: =CONCATENATE(AL8)
D9: Januari 2026 | N9: Februari 2026 | X9: Maret 2026 | AN9: =CONCATENATE(A9) | AO9: =CONCATENATE(B9) | AP9: =CONCATENATE(C9) | AQ9: Agustus | BA9: September | BK9: Oktober | BU9: =CONCATENATE(AH9) | BV9: =CONCATENATE(AI9) | BW9: =CONCATENATE(AJ9) | BX9: =CONCATENATE(AK9) | BY9: =CONCATENATE(AL9)
AI10: Sakit | AJ10: Ijin | AK10: Alfa | AL10: Total | AN10: =CONCATENATE(A10) | AO10: =CONCATENATE(B10) | AP10: =CONCATENATE(C10) | AQ10: 27 | BB10: 17 | BC10: 24 | BK10: 1 | BL10: 8 | BM10: 15 | BU10: =CONCATENATE(AH10) | BV10: =CONCATENATE(AI10) -> Sakit | BW10: =CONCATENATE(AJ10) -> Ijin | BX10: =CONCATENATE(AK10) -> Alfa | BY10: =CONCATENATE(AL10) -> Total
A11: 1 | B11: ALYA AZ-ZAHRA | C11: P | AH11: =IF(COUNTIF(D11:AG11,".")=0,"",COUNTIF(D11:AG11,".")) | AI11: =IF(COUNTIF(D11:AG11,"S")=0,"",COUNTIF(D11:AG11,"S")) | AJ11: =IF(COUNTIF(D11:AG11,"I")=0,"",COUNTIF(D11:AG11,"I")) | AK11: =IF(COUNTIF(D11:AG11,"A")=0,"",COUNTIF(D11:AG11,"A")) | AL11: =SUM(AI11:AK11) -> 0 | AN11: 1 | AO11: ADINDA PRABANDARI KINASIH | AP11: P | AQ11: . | BB11: . | BC11: . | BK11: . | BL11: . | BU11: =IF(COUNTIF(AQ11:BT11,".")=0,"",COUNTIF(AQ11:BT11,".")) -> 5 | BV11: =IF(COUNTIF(AQ11:BT11,"S")=0,"",COUNTIF(AQ11:BT11,"S")) | BW11: =IF(COUNTIF(AQ11:BT11,"I")=0,"",COUNTIF(AQ11:BT11,"I")) | BX11: =IF(COUNTIF(AQ11:BT11,"A")=0,"",COUNTIF(AQ11:BT11,"A")) | BY11: =SUM(BV11:BX11) -> 0
A12: 2 | B12: ARFA RAZIQ ADAM | C12: L | AH12: =IF(COUNTIF(D12:AG12,".")=0,"",COUNTIF(D12:AG12,".")) | AI12: =IF(COUNTIF(D12:AG12,"S")=0,"",COUNTIF(D12:AG12,"S")) | AJ12: =IF(COUNTIF(D12:AG12,"I")=0,"",COUNTIF(D12:AG12,"I")) | AK12: =IF(COUNTIF(D12:AG12,"A")=0,"",COUNTIF(D12:AG12,"A")) | AL12: =SUM(AI12:AK12) -> 0 | AN12: 2 | AO12: ALIFA MEYLANI SAFITRI | AP12: P | AQ12: . | BB12: . | BC12: . | BK12: . | BL12: . | BU12: =IF(COUNTIF(AQ12:BT12,".")=0,"",COUNTIF(AQ12:BT12,".")) -> 5 | BV12: =IF(COUNTIF(AQ12:BT12,"S")=0,"",COUNTIF(AQ12:BT12,"S")) | BW12: =IF(COUNTIF(AQ12:BT12,"I")=0,"",COUNTIF(AQ12:BT12,"I")) | BX12: =IF(COUNTIF(AQ12:BT12,"A")=0,"",COUNTIF(AQ12:BT12,"A")) | BY12: =SUM(BV12:BX12) -> 0
A13: 3 | B13: ARGADITYA RAHMAN HIRACAHYA | C13: L | AH13: =IF(COUNTIF(D13:AG13,".")=0,"",COUNTIF(D13:AG13,".")) | AI13: =IF(COUNTIF(D13:AG13,"S")=0,"",COUNTIF(D13:AG13,"S")) | AJ13: =IF(COUNTIF(D13:AG13,"I")=0,"",COUNTIF(D13:AG13,"I")) | AK13: =IF(COUNTIF(D13:AG13,"A")=0,"",COUNTIF(D13:AG13,"A")) | AL13: =SUM(AI13:AK13) -> 0 | AN13: 3 | AO13: AMALIA NURFADILAH | AP13: P | AQ13: . | BB13: . | BC13: . | BK13: . | BL13: . | BU13: =IF(COUNTIF(AQ13:BT13,".")=0,"",COUNTIF(AQ13:BT13,".")) -> 5 | BV13: =IF(COUNTIF(AQ13:BT13,"S")=0,"",COUNTIF(AQ13:BT13,"S")) | BW13: =IF(COUNTIF(AQ13:BT13,"I")=0,"",COUNTIF(AQ13:BT13,"I")) | BX13: =IF(COUNTIF(AQ13:BT13,"A")=0,"",COUNTIF(AQ13:BT13,"A")) | BY13: =SUM(BV13:BX13) -> 0
A14: 4 | B14: DAVIN RAISYA PRATAMA | C14: L | AH14: =IF(COUNTIF(D14:AG14,".")=0,"",COUNTIF(D14:AG14,".")) | AI14: =IF(COUNTIF(D14:AG14,"S")=0,"",COUNTIF(D14:AG14,"S")) | AJ14: =IF(COUNTIF(D14:AG14,"I")=0,"",COUNTIF(D14:AG14,"I")) | AK14: =IF(COUNTIF(D14:AG14,"A")=0,"",COUNTIF(D14:AG14,"A")) | AL14: =SUM(AI14:AK14) -> 0 | AN14: =CONCATENATE(A14) -> 4 | AO14: ARIA KUSUMAH | AP14: L | AQ14: . | BB14: . | BC14: . | BK14: s | BL14: . | BU14: =IF(COUNTIF(AQ14:BT14,".")=0,"",COUNTIF(AQ14:BT14,".")) -> 4 | BV14: =IF(COUNTIF(AQ14:BT14,"S")=0,"",COUNTIF(AQ14:BT14,"S")) -> 1 | BW14: =IF(COUNTIF(AQ14:BT14,"I")=0,"",COUNTIF(AQ14:BT14,"I")) | BX14: =IF(COUNTIF(AQ14:BT14,"A")=0,"",COUNTIF(AQ14:BT14,"A")) | BY14: =SUM(BV14:BX14) -> 1
A15: 5 | B15: DAVINA CHERRYL AGIESYA | C15: P | AH15: =IF(COUNTIF(D15:AG15,".")=0,"",COUNTIF(D15:AG15,".")) | AI15: =IF(COUNTIF(D15:AG15,"S")=0,"",COUNTIF(D15:AG15,"S")) | AJ15: =IF(COUNTIF(D15:AG15,"I")=0,"",COUNTIF(D15:AG15,"I")) | AK15: =IF(COUNTIF(D15:AG15,"A")=0,"",COUNTIF(D15:AG15,"A")) | AL15: =SUM(AI15:AK15) -> 0 | AN15: =CONCATENATE(A15) -> 5 | AO15: AULIA KINASIH | AP15: P | AQ15: . | BB15: . | BC15: . | BK15: s | BL15: . | BU15: =IF(COUNTIF(AQ15:BT15,".")=0,"",COUNTIF(AQ15:BT15,".")) -> 4 | BV15: =IF(COUNTIF(AQ15:BT15,"S")=0,"",COUNTIF(AQ15:BT15,"S")) -> 1 | BW15: =IF(COUNTIF(AQ15:BT15,"I")=0,"",COUNTIF(AQ15:BT15,"I")) | BX15: =IF(COUNTIF(AQ15:BT15,"A")=0,"",COUNTIF(AQ15:BT15,"A")) | BY15: =SUM(BV15:BX15) -> 1
A16: 6 | B16: FARHAN GARNADI | C16: L | AH16: =IF(COUNTIF(D16:AG16,".")=0,"",COUNTIF(D16:AG16,".")) | AI16: =IF(COUNTIF(D16:AG16,"S")=0,"",COUNTIF(D16:AG16,"S")) | AJ16: =IF(COUNTIF(D16:AG16,"I")=0,"",COUNTIF(D16:AG16,"I")) | AK16: =IF(COUNTIF(D16:AG16,"A")=0,"",COUNTIF(D16:AG16,"A")) | AL16: =SUM(AI16:AK16) -> 0 | AN16: =CONCATENATE(A16) -> 6 | AO16: BALQIS FANIDA SORAYA | AP16: P | AQ16: . | BB16: . | BC16: . | BK16: . | BL16: . | BU16: =IF(COUNTIF(AQ16:BT16,".")=0,"",COUNTIF(AQ16:BT16,".")) -> 5 | BV16: =IF(COUNTIF(AQ16:BT16,"S")=0,"",COUNTIF(AQ16:BT16,"S")) | BW16: =IF(COUNTIF(AQ16:BT16,"I")=0,"",COUNTIF(AQ16:BT16,"I")) | BX16: =IF(COUNTIF(AQ16:BT16,"A")=0,"",COUNTIF(AQ16:BT16,"A")) | BY16: =SUM(BV16:BX16) -> 0
A17: 7 | B17: FARID NAUFAL IDLAN | C17: L | AH17: =IF(COUNTIF(D17:AG17,".")=0,"",COUNTIF(D17:AG17,".")) | AI17: =IF(COUNTIF(D17:AG17,"S")=0,"",COUNTIF(D17:AG17,"S")) | AJ17: =IF(COUNTIF(D17:AG17,"I")=0,"",COUNTIF(D17:AG17,"I")) | AK17: =IF(COUNTIF(D17:AG17,"A")=0,"",COUNTIF(D17:AG17,"A")) | AL17: =SUM(AI17:AK17) -> 0 | AN17: =CONCATENATE(A17) -> 7 | AO17: CAHYA ISMAIL | AP17: L | AQ17: . | BB17: . | BC17: . | BK17: . | BL17: . | BU17: =IF(COUNTIF(AQ17:BT17,".")=0,"",COUNTIF(AQ17:BT17,".")) -> 5 | BV17: =IF(COUNTIF(AQ17:BT17,"S")=0,"",COUNTIF(AQ17:BT17,"S")) | BW17: =IF(COUNTIF(AQ17:BT17,"I")=0,"",COUNTIF(AQ17:BT17,"I")) | BX17: =IF(COUNTIF(AQ17:BT17,"A")=0,"",COUNTIF(AQ17:BT17,"A")) | BY17: =SUM(BV17:BX17) -> 0
A18: 8 | B18: FRESHA INDAH ELVIANNISA | C18: P | AH18: =IF(COUNTIF(D18:AG18,".")=0,"",COUNTIF(D18:AG18,".")) | AI18: =IF(COUNTIF(D18:AG18,"S")=0,"",COUNTIF(D18:AG18,"S")) | AJ18: =IF(COUNTIF(D18:AG18,"I")=0,"",COUNTIF(D18:AG18,"I")) | AK18: =IF(COUNTIF(D18:AG18,"A")=0,"",COUNTIF(D18:AG18,"A")) | AL18: =SUM(AI18:AK18) -> 0 | AN18: =CONCATENATE(A18) -> 8 | AO18: CHIARA HASNA ZHAFIRA | AP18: P | AQ18: . | BB18: s | BC18: . | BK18: . | BL18: . | BU18: =IF(COUNTIF(AQ18:BT18,".")=0,"",COUNTIF(AQ18:BT18,".")) -> 4 | BV18: =IF(COUNTIF(AQ18:BT18,"S")=0,"",COUNTIF(AQ18:BT18,"S")) -> 1 | BW18: =IF(COUNTIF(AQ18:BT18,"I")=0,"",COUNTIF(AQ18:BT18,"I")) | BX18: =IF(COUNTIF(AQ18:BT18,"A")=0,"",COUNTIF(AQ18:BT18,"A")) | BY18: =SUM(BV18:BX18) -> 1
A19: 9 | B19: GHANI YAZID KHAIRI | C19: L | AH19: =IF(COUNTIF(D19:AG19,".")=0,"",COUNTIF(D19:AG19,".")) | AI19: =IF(COUNTIF(D19:AG19,"S")=0,"",COUNTIF(D19:AG19,"S")) | AJ19: =IF(COUNTIF(D19:AG19,"I")=0,"",COUNTIF(D19:AG19,"I")) | AK19: =IF(COUNTIF(D19:AG19,"A")=0,"",COUNTIF(D19:AG19,"A")) | AL19: =SUM(AI19:AK19) -> 0 | AN19: =CONCATENATE(A19) -> 9 | AO19: DEVILIA AULIA PUTRI | AP19: P | AQ19: s | BB19: . | BC19: . | BK19: . | BL19: . | BU19: =IF(COUNTIF(AQ19:BT19,".")=0,"",COUNTIF(AQ19:BT19,".")) -> 4 | BV19: =IF(COUNTIF(AQ19:BT19,"S")=0,"",COUNTIF(AQ19:BT19,"S")) -> 1 | BW19: =IF(COUNTIF(AQ19:BT19,"I")=0,"",COUNTIF(AQ19:BT19,"I")) | BX19: =IF(COUNTIF(AQ19:BT19,"A")=0,"",COUNTIF(AQ19:BT19,"A")) | BY19: =SUM(BV19:BX19) -> 1
A20: 10 | B20: GUSNI RAMADHANI | C20: L | AH20: =IF(COUNTIF(D20:AG20,".")=0,"",COUNTIF(D20:AG20,".")) | AI20: =IF(COUNTIF(D20:AG20,"S")=0,"",COUNTIF(D20:AG20,"S")) | AJ20: =IF(COUNTIF(D20:AG20,"I")=0,"",COUNTIF(D20:AG20,"I")) | AK20: =IF(COUNTIF(D20:AG20,"A")=0,"",COUNTIF(D20:AG20,"A")) | AL20: =SUM(AI20:AK20) -> 0 | AN20: =CONCATENATE(A20) -> 10 | AO20: EGA YUDA NUGRAHA | AP20: L | AQ20: . | BB20: . | BC20: . | BK20: s | BL20: . | BU20: =IF(COUNTIF(AQ20:BT20,".")=0,"",COUNTIF(AQ20:BT20,".")) -> 4 | BV20: =IF(COUNTIF(AQ20:BT20,"S")=0,"",COUNTIF(AQ20:BT20,"S")) -> 1 | BW20: =IF(COUNTIF(AQ20:BT20,"I")=0,"",COUNTIF(AQ20:BT20,"I")) | BX20: =IF(COUNTIF(AQ20:BT20,"A")=0,"",COUNTIF(AQ20:BT20,"A")) | BY20: =SUM(BV20:BX20) -> 1
A21: 11 | B21: HANIEF AWWAL ABDILLAH | C21: L | AH21: =IF(COUNTIF(D21:AG21,".")=0,"",COUNTIF(D21:AG21,".")) | AI21: =IF(COUNTIF(D21:AG21,"S")=0,"",COUNTIF(D21:AG21,"S")) | AJ21: =IF(COUNTIF(D21:AG21,"I")=0,"",COUNTIF(D21:AG21,"I")) | AK21: =IF(COUNTIF(D21:AG21,"A")=0,"",COUNTIF(D21:AG21,"A")) | AL21: =SUM(AI21:AK21) -> 0 | AN21: =CONCATENATE(A21) -> 11 | AO21: ELMIRA ZAHIYA RUSDI | AP21: P | AQ21: . | BB21: . | BC21: . | BK21: . | BL21: . | BU21: =IF(COUNTIF(AQ21:BT21,".")=0,"",COUNTIF(AQ21:BT21,".")) -> 5 | BV21: =IF(COUNTIF(AQ21:BT21,"S")=0,"",COUNTIF(AQ21:BT21,"S")) | BW21: =IF(COUNTIF(AQ21:BT21,"I")=0,"",COUNTIF(AQ21:BT21,"I")) | BX21: =IF(COUNTIF(AQ21:BT21,"A")=0,"",COUNTIF(AQ21:BT21,"A")) | BY21: =SUM(BV21:BX21) -> 0
A22: 12 | B22: JIBRIL AL FAUZAN PURNADI | C22: L | AH22: =IF(COUNTIF(D22:AG22,".")=0,"",COUNTIF(D22:AG22,".")) | AI22: =IF(COUNTIF(D22:AG22,"S")=0,"",COUNTIF(D22:AG22,"S")) | AJ22: =IF(COUNTIF(D22:AG22,"I")=0,"",COUNTIF(D22:AG22,"I")) | AK22: =IF(COUNTIF(D22:AG22,"A")=0,"",COUNTIF(D22:AG22,"A")) | AL22: =SUM(AI22:AK22) -> 0 | AN22: =CONCATENATE(A22) -> 12 | AO22: FAHRAN FATUROHMAN | AP22: L | AQ22: . | BB22: . | BC22: . | BK22: . | BL22: . | BU22: =IF(COUNTIF(AQ22:BT22,".")=0,"",COUNTIF(AQ22:BT22,".")) -> 5 | BV22: =IF(COUNTIF(AQ22:BT22,"S")=0,"",COUNTIF(AQ22:BT22,"S")) | BW22: =IF(COUNTIF(AQ22:BT22,"I")=0,"",COUNTIF(AQ22:BT22,"I")) | BX22: =IF(COUNTIF(AQ22:BT22,"A")=0,"",COUNTIF(AQ22:BT22,"A")) | BY22: =SUM(BV22:BX22) -> 0
A23: 13 | B23: JULVIKY ARUN KSATRIA | C23: L | AH23: =IF(COUNTIF(D23:AG23,".")=0,"",COUNTIF(D23:AG23,".")) | AI23: =IF(COUNTIF(D23:AG23,"S")=0,"",COUNTIF(D23:AG23,"S")) | AJ23: =IF(COUNTIF(D23:AG23,"I")=0,"",COUNTIF(D23:AG23,"I")) | AK23: =IF(COUNTIF(D23:AG23,"A")=0,"",COUNTIF(D23:AG23,"A")) | AL23: =SUM(AI23:AK23) -> 0 | AN23: =CONCATENATE(A23) -> 13 | AO23: FAKHIRA SALWA NABILA | AP23: P | AQ23: . | BB23: . | BC23: . | BK23: . | BL23: . | BU23: =IF(COUNTIF(AQ23:BT23,".")=0,"",COUNTIF(AQ23:BT23,".")) -> 5 | BV23: =IF(COUNTIF(AQ23:BT23,"S")=0,"",COUNTIF(AQ23:BT23,"S")) | BW23: =IF(COUNTIF(AQ23:BT23,"I")=0,"",COUNTIF(AQ23:BT23,"I")) | BX23: =IF(COUNTIF(AQ23:BT23,"A")=0,"",COUNTIF(AQ23:BT23,"A")) | BY23: =SUM(BV23:BX23) -> 0
A24: P | B24: KANIA ALESHA RIFAYA | C24: P | AH24: =IF(COUNTIF(D24:AG24,".")=0,"",COUNTIF(D24:AG24,".")) | AI24: =IF(COUNTIF(D24:AG24,"S")=0,"",COUNTIF(D24:AG24,"S")) | AJ24: =IF(COUNTIF(D24:AG24,"I")=0,"",COUNTIF(D24:AG24,"I")) | AK24: =IF(COUNTIF(D24:AG24,"A")=0,"",COUNTIF(D24:AG24,"A")) | AL24: =SUM(AI24:AK24) -> 0 | AN24: 14 | AO24: FATHIYYA AMEERA QUEENNARRA EDWARD | AP24: P | AQ24: . | BB24: . | BC24: . | BK24: . | BL24: . | BU24: =IF(COUNTIF(AQ24:BT24,".")=0,"",COUNTIF(AQ24:BT24,".")) -> 5 | BV24: =IF(COUNTIF(AQ24:BT24,"S")=0,"",COUNTIF(AQ24:BT24,"S")) | BW24: =IF(COUNTIF(AQ24:BT24,"I")=0,"",COUNTIF(AQ24:BT24,"I")) | BX24: =IF(COUNTIF(AQ24:BT24,"A")=0,"",COUNTIF(AQ24:BT24,"A")) | BY24: =SUM(BV24:BX24) -> 0
A25: 15 | B25: LINTANG AKASHA DIPUTRA SULAIMAN | C25: L | AH25: =IF(COUNTIF(D25:AG25,".")=0,"",COUNTIF(D25:AG25,".")) | AI25: =IF(COUNTIF(D25:AG25,"S")=0,"",COUNTIF(D25:AG25,"S")) | AJ25: =IF(COUNTIF(D25:AG25,"I")=0,"",COUNTIF(D25:AG25,"I")) | AK25: =IF(COUNTIF(D25:AG25,"A")=0,"",COUNTIF(D25:AG25,"A")) | AL25: =SUM(AI25:AK25) -> 0 | AN25: =CONCATENATE(A25) -> 15 | AO25: FAUZAN SYAWAL PRATAMA | AP25: L | AQ25: . | BB25: . | BC25: . | BK25: . | BL25: . | BU25: =IF(COUNTIF(AQ25:BT25,".")=0,"",COUNTIF(AQ25:BT25,".")) -> 5 | BV25: =IF(COUNTIF(AQ25:BT25,"S")=0,"",COUNTIF(AQ25:BT25,"S")) | BW25: =IF(COUNTIF(AQ25:BT25,"I")=0,"",COUNTIF(AQ25:BT25,"I")) | BX25: =IF(COUNTIF(AQ25:BT25,"A")=0,"",COUNTIF(AQ25:BT25,"A")) | BY25: =SUM(BV25:BX25) -> 0
A26: 16 | B26: MARITZA JESSENIA ZAYYAN | C26: P | AH26: =IF(COUNTIF(D26:AG26,".")=0,"",COUNTIF(D26:AG26,".")) | AI26: =IF(COUNTIF(D26:AG26,"S")=0,"",COUNTIF(D26:AG26,"S")) | AJ26: =IF(COUNTIF(D26:AG26,"I")=0,"",COUNTIF(D26:AG26,"I")) | AK26: =IF(COUNTIF(D26:AG26,"A")=0,"",COUNTIF(D26:AG26,"A")) | AL26: =SUM(AI26:AK26) -> 0 | AN26: =CONCATENATE(A26) -> 16 | AO26: GHEA RAHMAYANI | AP26: P | AQ26: . | BB26: . | BC26: . | BK26: . | BL26: . | BU26: =IF(COUNTIF(AQ26:BT26,".")=0,"",COUNTIF(AQ26:BT26,".")) -> 5 | BV26: =IF(COUNTIF(AQ26:BT26,"S")=0,"",COUNTIF(AQ26:BT26,"S")) | BW26: =IF(COUNTIF(AQ26:BT26,"I")=0,"",COUNTIF(AQ26:BT26,"I")) | BX26: =IF(COUNTIF(AQ26:BT26,"A")=0,"",COUNTIF(AQ26:BT26,"A")) | BY26: =SUM(BV26:BX26) -> 0
A27: 17 | B27: MARVELINO YAKUB PANDAPOTAN ARITONANG | C27: L | AH27: =IF(COUNTIF(D27:AG27,".")=0,"",COUNTIF(D27:AG27,".")) | AI27: =IF(COUNTIF(D27:AG27,"S")=0,"",COUNTIF(D27:AG27,"S")) | AJ27: =IF(COUNTIF(D27:AG27,"I")=0,"",COUNTIF(D27:AG27,"I")) | AK27: =IF(COUNTIF(D27:AG27,"A")=0,"",COUNTIF(D27:AG27,"A")) | AL27: =SUM(AI27:AK27) -> 0 | AN27: =CONCATENATE(A27) -> 17 | AO27: INTANIA RAMADANIA | AP27: P | AQ27: . | BB27: . | BC27: . | BK27: . | BL27: . | BU27: =IF(COUNTIF(AQ27:BT27,".")=0,"",COUNTIF(AQ27:BT27,".")) -> 5 | BV27: =IF(COUNTIF(AQ27:BT27,"S")=0,"",COUNTIF(AQ27:BT27,"S")) | BW27: =IF(COUNTIF(AQ27:BT27,"I")=0,"",COUNTIF(AQ27:BT27,"I")) | BX27: =IF(COUNTIF(AQ27:BT27,"A")=0,"",COUNTIF(AQ27:BT27,"A")) | BY27: =SUM(BV27:BX27) -> 0
A28: 18 | B28: MOSES GABE PARULIAN BUTAR-BUTAR | C28: L | AH28: =IF(COUNTIF(D28:AG28,".")=0,"",COUNTIF(D28:AG28,".")) | AI28: =IF(COUNTIF(D28:AG28,"S")=0,"",COUNTIF(D28:AG28,"S")) | AJ28: =IF(COUNTIF(D28:AG28,"I")=0,"",COUNTIF(D28:AG28,"I")) | AK28: =IF(COUNTIF(D28:AG28,"A")=0,"",COUNTIF(D28:AG28,"A")) | AL28: =SUM(AI28:AK28) -> 0 | AN28: =CONCATENATE(A28) -> 18 | AO28: JAUZA HANA NABILA | AP28: P | AQ28: . | BB28: . | BC28: . | BK28: . | BL28: . | BU28: =IF(COUNTIF(AQ28:BT28,".")=0,"",COUNTIF(AQ28:BT28,".")) -> 5 | BV28: =IF(COUNTIF(AQ28:BT28,"S")=0,"",COUNTIF(AQ28:BT28,"S")) | BW28: =IF(COUNTIF(AQ28:BT28,"I")=0,"",COUNTIF(AQ28:BT28,"I")) | BX28: =IF(COUNTIF(AQ28:BT28,"A")=0,"",COUNTIF(AQ28:BT28,"A")) | BY28: =SUM(BV28:BX28) -> 0
A29: 19 | B29: MUHAMMAD AKMAL FIRDAUS | C29: L | AH29: =IF(COUNTIF(D29:AG29,".")=0,"",COUNTIF(D29:AG29,".")) | AI29: =IF(COUNTIF(D29:AG29,"S")=0,"",COUNTIF(D29:AG29,"S")) | AJ29: =IF(COUNTIF(D29:AG29,"I")=0,"",COUNTIF(D29:AG29,"I")) | AK29: =IF(COUNTIF(D29:AG29,"A")=0,"",COUNTIF(D29:AG29,"A")) | AL29: =SUM(AI29:AK29) -> 0 | AN29: =CONCATENATE(A29) -> 19 | AO29: KEYSHA NUR RAHAYU | AP29: P | AQ29: . | BB29: . | BC29: . | BK29: . | BL29: . | BU29: =IF(COUNTIF(AQ29:BT29,".")=0,"",COUNTIF(AQ29:BT29,".")) -> 5 | BV29: =IF(COUNTIF(AQ29:BT29,"S")=0,"",COUNTIF(AQ29:BT29,"S")) | BW29: =IF(COUNTIF(AQ29:BT29,"I")=0,"",COUNTIF(AQ29:BT29,"I")) | BX29: =IF(COUNTIF(AQ29:BT29,"A")=0,"",COUNTIF(AQ29:BT29,"A")) | BY29: =SUM(BV29:BX29) -> 0
A30: 21 | B30: MUHAMMAD DAFFA ABDILLAH | C30: L | AH30: =IF(COUNTIF(D30:AG30,".")=0,"",COUNTIF(D30:AG30,".")) | AI30: =IF(COUNTIF(D30:AG30,"S")=0,"",COUNTIF(D30:AG30,"S")) | AJ30: =IF(COUNTIF(D30:AG30,"I")=0,"",COUNTIF(D30:AG30,"I")) | AK30: =IF(COUNTIF(D30:AG30,"A")=0,"",COUNTIF(D30:AG30,"A")) | AL30: =SUM(AI30:AK30) -> 0 | AN30: 20 | AO30: MAHESYA LILY | AP30: P | AQ30: . | BB30: . | BC30: . | BK30: . | BL30: . | BU30: =IF(COUNTIF(AQ30:BT30,".")=0,"",COUNTIF(AQ30:BT30,".")) -> 5 | BV30: =IF(COUNTIF(AQ30:BT30,"S")=0,"",COUNTIF(AQ30:BT30,"S")) | BW30: =IF(COUNTIF(AQ30:BT30,"I")=0,"",COUNTIF(AQ30:BT30,"I")) | BX30: =IF(COUNTIF(AQ30:BT30,"A")=0,"",COUNTIF(AQ30:BT30,"A")) | BY30: =SUM(BV30:BX30) -> 0
A31: 22 | B31: MUHAMMAD HILMI AD-DZIKRI | C31: L | AH31: =IF(COUNTIF(D31:AG31,".")=0,"",COUNTIF(D31:AG31,".")) | AI31: =IF(COUNTIF(D31:AG31,"S")=0,"",COUNTIF(D31:AG31,"S")) | AJ31: =IF(COUNTIF(D31:AG31,"I")=0,"",COUNTIF(D31:AG31,"I")) | AK31: =IF(COUNTIF(D31:AG31,"A")=0,"",COUNTIF(D31:AG31,"A")) | AL31: =SUM(AI31:AK31) -> 0 | AN31: 21 | AO31: MALVIN AKSATRYA DANISWARA KUSMANA | AP31: L | AQ31: . | BB31: . | BC31: . | BK31: . | BL31: . | BU31: =IF(COUNTIF(AQ31:BT31,".")=0,"",COUNTIF(AQ31:BT31,".")) -> 5 | BV31: =IF(COUNTIF(AQ31:BT31,"S")=0,"",COUNTIF(AQ31:BT31,"S")) | BW31: =IF(COUNTIF(AQ31:BT31,"I")=0,"",COUNTIF(AQ31:BT31,"I")) | BX31: =IF(COUNTIF(AQ31:BT31,"A")=0,"",COUNTIF(AQ31:BT31,"A")) | BY31: =SUM(BV31:BX31) -> 0
A32: 23 | B32: MUHAMMAD SYARIF ROMDHONI | C32: L | AH32: =IF(COUNTIF(D32:AG32,".")=0,"",COUNTIF(D32:AG32,".")) | AI32: =IF(COUNTIF(D32:AG32,"S")=0,"",COUNTIF(D32:AG32,"S")) | AJ32: =IF(COUNTIF(D32:AG32,"I")=0,"",COUNTIF(D32:AG32,"I")) | AK32: =IF(COUNTIF(D32:AG32,"A")=0,"",COUNTIF(D32:AG32,"A")) | AL32: =SUM(AI32:AK32) -> 0 | AN32: 22 | AO32: MARWA NURHAA NAFIAH | AP32: P | AQ32: . | BB32: . | BC32: . | BK32: . | BL32: . | BU32: =IF(COUNTIF(AQ32:BT32,".")=0,"",COUNTIF(AQ32:BT32,".")) -> 5 | BV32: =IF(COUNTIF(AQ32:BT32,"S")=0,"",COUNTIF(AQ32:BT32,"S")) | BW32: =IF(COUNTIF(AQ32:BT32,"I")=0,"",COUNTIF(AQ32:BT32,"I")) | BX32: =IF(COUNTIF(AQ32:BT32,"A")=0,"",COUNTIF(AQ32:BT32,"A")) | BY32: =SUM(BV32:BX32) -> 0
A33: 24 | B33: MUTIARA NUR SYIFA | C33: P | AH33: =IF(COUNTIF(D33:AG33,".")=0,"",COUNTIF(D33:AG33,".")) | AI33: =IF(COUNTIF(D33:AG33,"S")=0,"",COUNTIF(D33:AG33,"S")) | AJ33: =IF(COUNTIF(D33:AG33,"I")=0,"",COUNTIF(D33:AG33,"I")) | AK33: =IF(COUNTIF(D33:AG33,"A")=0,"",COUNTIF(D33:AG33,"A")) | AL33: =SUM(AI33:AK33) -> 0 | AN33: 23 | AO33: MIKAIL AL KAUTSAR SIMA PAWITRA | AP33: L | AQ33: . | BB33: . | BC33: . | BK33: . | BL33: . | BU33: =IF(COUNTIF(AQ33:BT33,".")=0,"",COUNTIF(AQ33:BT33,".")) -> 5 | BV33: =IF(COUNTIF(AQ33:BT33,"S")=0,"",COUNTIF(AQ33:BT33,"S")) | BW33: =IF(COUNTIF(AQ33:BT33,"I")=0,"",COUNTIF(AQ33:BT33,"I")) | BX33: =IF(COUNTIF(AQ33:BT33,"A")=0,"",COUNTIF(AQ33:BT33,"A")) | BY33: =SUM(BV33:BX33) -> 0
A34: 25 | B34: NABIL MOHAMMAD AZMII AKRAM | C34: L | AH34: =IF(COUNTIF(D34:AG34,".")=0,"",COUNTIF(D34:AG34,".")) | AI34: =IF(COUNTIF(D34:AG34,"S")=0,"",COUNTIF(D34:AG34,"S")) | AJ34: =IF(COUNTIF(D34:AG34,"I")=0,"",COUNTIF(D34:AG34,"I")) | AK34: =IF(COUNTIF(D34:AG34,"A")=0,"",COUNTIF(D34:AG34,"A")) | AL34: =SUM(AI34:AK34) -> 0 | AN34: 24 | AO34: MUHAMAD AGUNG RIVA RISQULOH | AP34: L | AQ34: s | BB34: . | BC34: . | BK34: . | BL34: s | BU34: =IF(COUNTIF(AQ34:BT34,".")=0,"",COUNTIF(AQ34:BT34,".")) -> 3 | BV34: =IF(COUNTIF(AQ34:BT34,"S")=0,"",COUNTIF(AQ34:BT34,"S")) -> 2 | BW34: =IF(COUNTIF(AQ34:BT34,"I")=0,"",COUNTIF(AQ34:BT34,"I")) | BX34: =IF(COUNTIF(AQ34:BT34,"A")=0,"",COUNTIF(AQ34:BT34,"A")) | BY34: =SUM(BV34:BX34) -> 2
A35: 26 | B35: NADINE GAZA AULYA | C35: P | AH35: =IF(COUNTIF(D35:AG35,".")=0,"",COUNTIF(D35:AG35,".")) | AI35: =IF(COUNTIF(D35:AG35,"S")=0,"",COUNTIF(D35:AG35,"S")) | AJ35: =IF(COUNTIF(D35:AG35,"I")=0,"",COUNTIF(D35:AG35,"I")) | AK35: =IF(COUNTIF(D35:AG35,"A")=0,"",COUNTIF(D35:AG35,"A")) | AL35: =SUM(AI35:AK35) -> 0 | AN35: 25 | AO35: MUHAMAD FAJAR DWI PUTRA | AP35: L | AQ35: . | BB35: . | BC35: . | BK35: . | BL35: . | BU35: =IF(COUNTIF(AQ35:BT35,".")=0,"",COUNTIF(AQ35:BT35,".")) -> 5 | BV35: =IF(COUNTIF(AQ35:BT35,"S")=0,"",COUNTIF(AQ35:BT35,"S")) | BW35: =IF(COUNTIF(AQ35:BT35,"I")=0,"",COUNTIF(AQ35:BT35,"I")) | BX35: =IF(COUNTIF(AQ35:BT35,"A")=0,"",COUNTIF(AQ35:BT35,"A")) | BY35: =SUM(BV35:BX35) -> 0
A36: 27 | B36: NIRVANAZIA SARWAHITA AJIWARA | C36: P | AH36: =IF(COUNTIF(D36:AG36,".")=0,"",COUNTIF(D36:AG36,".")) | AI36: =IF(COUNTIF(D36:AG36,"S")=0,"",COUNTIF(D36:AG36,"S")) | AJ36: =IF(COUNTIF(D36:AG36,"I")=0,"",COUNTIF(D36:AG36,"I")) | AK36: =IF(COUNTIF(D36:AG36,"A")=0,"",COUNTIF(D36:AG36,"A")) | AL36: =SUM(AI36:AK36) -> 0 | AN36: 26 | AO36: MUHAMAD PAHMI PUTRA SANGGARA | AP36: L | AQ36: s | BB36: . | BC36: . | BK36: . | BL36: . | BU36: =IF(COUNTIF(AQ36:BT36,".")=0,"",COUNTIF(AQ36:BT36,".")) -> 4 | BV36: =IF(COUNTIF(AQ36:BT36,"S")=0,"",COUNTIF(AQ36:BT36,"S")) -> 1 | BW36: =IF(COUNTIF(AQ36:BT36,"I")=0,"",COUNTIF(AQ36:BT36,"I")) | BX36: =IF(COUNTIF(AQ36:BT36,"A")=0,"",COUNTIF(AQ36:BT36,"A")) | BY36: =SUM(BV36:BX36) -> 1
A37: 28 | B37: PARAS SANDERIANA ARDIAN | C37: P | AH37: =IF(COUNTIF(D37:AG37,".")=0,"",COUNTIF(D37:AG37,".")) | AI37: =IF(COUNTIF(D37:AG37,"S")=0,"",COUNTIF(D37:AG37,"S")) | AJ37: =IF(COUNTIF(D37:AG37,"I")=0,"",COUNTIF(D37:AG37,"I")) | AK37: =IF(COUNTIF(D37:AG37,"A")=0,"",COUNTIF(D37:AG37,"A")) | AL37: =SUM(AI37:AK37) -> 0 | AN37: 27 | AO37: MUHAMMAD AZRIL ILHAM | AP37: L | AQ37: . | BB37: . | BC37: . | BK37: . | BL37: s | BU37: =IF(COUNTIF(AQ37:BT37,".")=0,"",COUNTIF(AQ37:BT37,".")) -> 4 | BV37: =IF(COUNTIF(AQ37:BT37,"S")=0,"",COUNTIF(AQ37:BT37,"S")) -> 1 | BW37: =IF(COUNTIF(AQ37:BT37,"I")=0,"",COUNTIF(AQ37:BT37,"I")) | BX37: =IF(COUNTIF(AQ37:BT37,"A")=0,"",COUNTIF(AQ37:BT37,"A")) | BY37: =SUM(BV37:BX37) -> 1
A38: 29 | B38: RAGIL SARASWATI | C38: P | AH38: =IF(COUNTIF(D38:AG38,".")=0,"",COUNTIF(D38:AG38,".")) | AI38: =IF(COUNTIF(D38:AG38,"S")=0,"",COUNTIF(D38:AG38,"S")) | AJ38: =IF(COUNTIF(D38:AG38,"I")=0,"",COUNTIF(D38:AG38,"I")) | AK38: =IF(COUNTIF(D38:AG38,"A")=0,"",COUNTIF(D38:AG38,"A")) | AL38: =SUM(AI38:AK38) -> 0 | AN38: 28 | AO38: MUHAMMAD KAFI AL-FATIH | AP38: L | AQ38: . | BB38: . | BC38: . | BK38: . | BL38: . | BU38: =IF(COUNTIF(AQ38:BT38,".")=0,"",COUNTIF(AQ38:BT38,".")) -> 5 | BV38: =IF(COUNTIF(AQ38:BT38,"S")=0,"",COUNTIF(AQ38:BT38,"S")) | BW38: =IF(COUNTIF(AQ38:BT38,"I")=0,"",COUNTIF(AQ38:BT38,"I")) | BX38: =IF(COUNTIF(AQ38:BT38,"A")=0,"",COUNTIF(AQ38:BT38,"A")) | BY38: =SUM(BV38:BX38) -> 0
A39: 30 | B39: RAJWA DANISWARA RUSPANDI | C39: L | AH39: =IF(COUNTIF(D39:AG39,".")=0,"",COUNTIF(D39:AG39,".")) | AI39: =IF(COUNTIF(D39:AG39,"S")=0,"",COUNTIF(D39:AG39,"S")) | AJ39: =IF(COUNTIF(D39:AG39,"I")=0,"",COUNTIF(D39:AG39,"I")) | AK39: =IF(COUNTIF(D39:AG39,"A")=0,"",COUNTIF(D39:AG39,"A")) | AL39: =SUM(AI39:AK39) -> 0 | AN39: 29 | AO39: MUHAMMAD KARIZA AL FAKHRI | AP39: L | AQ39: . | BB39: . | BC39: . | BK39: s | BL39: . | BU39: =IF(COUNTIF(AQ39:BT39,".")=0,"",COUNTIF(AQ39:BT39,".")) -> 4 | BV39: =IF(COUNTIF(AQ39:BT39,"S")=0,"",COUNTIF(AQ39:BT39,"S")) -> 1 | BW39: =IF(COUNTIF(AQ39:BT39,"I")=0,"",COUNTIF(AQ39:BT39,"I")) | BX39: =IF(COUNTIF(AQ39:BT39,"A")=0,"",COUNTIF(AQ39:BT39,"A")) | BY39: =SUM(BV39:BX39) -> 1
A40: 31 | B40: RITA MAY LUTVIYANI | C40: P | AH40: =IF(COUNTIF(D40:AG40,".")=0,"",COUNTIF(D40:AG40,".")) | AI40: =IF(COUNTIF(D40:AG40,"S")=0,"",COUNTIF(D40:AG40,"S")) | AJ40: =IF(COUNTIF(D40:AG40,"I")=0,"",COUNTIF(D40:AG40,"I")) | AK40: =IF(COUNTIF(D40:AG40,"A")=0,"",COUNTIF(D40:AG40,"A")) | AL40: =SUM(AI40:AK40) -> 0 | AN40: 30 | AO40: MUHAMMAD MAHIN | AP40: L | AQ40: . | BC40: . | BK40: . | BL40: . | BU40: =IF(COUNTIF(AQ40:BT40,".")=0,"",COUNTIF(AQ40:BT40,".")) -> 4 | BV40: =IF(COUNTIF(AQ40:BT40,"S")=0,"",COUNTIF(AQ40:BT40,"S")) | BW40: =IF(COUNTIF(AQ40:BT40,"I")=0,"",COUNTIF(AQ40:BT40,"I")) | BX40: =IF(COUNTIF(AQ40:BT40,"A")=0,"",COUNTIF(AQ40:BT40,"A")) | BY40: =SUM(BV40:BX40) -> 0
A41: 32 | B41: RIZKYTA PRAWINA KUSUMA | C41: P | AH41: =IF(COUNTIF(D41:AG41,".")=0,"",COUNTIF(D41:AG41,".")) | AI41: =IF(COUNTIF(D41:AG41,"S")=0,"",COUNTIF(D41:AG41,"S")) | AJ41: =IF(COUNTIF(D41:AG41,"I")=0,"",COUNTIF(D41:AG41,"I")) | AK41: =IF(COUNTIF(D41:AG41,"A")=0,"",COUNTIF(D41:AG41,"A")) | AL41: =SUM(AI41:AK41) -> 0 | AN41: 31 | AO41: MUHAMMAD WILDAN FIRDAUS | AP41: L | AQ41: . | BB41: . | BC41: . | BK41: . | BL41: . | BU41: =IF(COUNTIF(AQ41:BT41,".")=0,"",COUNTIF(AQ41:BT41,".")) -> 5 | BV41: =IF(COUNTIF(AQ41:BT41,"S")=0,"",COUNTIF(AQ41:BT41,"S")) | BW41: =IF(COUNTIF(AQ41:BT41,"I")=0,"",COUNTIF(AQ41:BT41,"I")) | BX41: =IF(COUNTIF(AQ41:BT41,"A")=0,"",COUNTIF(AQ41:BT41,"A")) | BY41: =SUM(BV41:BX41) -> 0
A42: 33 | B42: RIZQI FEBRIAN | C42: L | AH42: =IF(COUNTIF(D42:AG42,".")=0,"",COUNTIF(D42:AG42,".")) | AI42: =IF(COUNTIF(D42:AG42,"S")=0,"",COUNTIF(D42:AG42,"S")) | AJ42: =IF(COUNTIF(D42:AG42,"I")=0,"",COUNTIF(D42:AG42,"I")) | AK42: =IF(COUNTIF(D42:AG42,"A")=0,"",COUNTIF(D42:AG42,"A")) | AL42: =SUM(AI42:AK42) -> 0 | AN42: 32 | AO42: NAILA DZIKRIA AZMI | AP42: P | AQ42: . | BB42: . | BC42: . | BK42: . | BL42: . | BU42: =IF(COUNTIF(AQ42:BT42,".")=0,"",COUNTIF(AQ42:BT42,".")) -> 5 | BV42: =IF(COUNTIF(AQ42:BT42,"S")=0,"",COUNTIF(AQ42:BT42,"S")) | BW42: =IF(COUNTIF(AQ42:BT42,"I")=0,"",COUNTIF(AQ42:BT42,"I")) | BX42: =IF(COUNTIF(AQ42:BT42,"A")=0,"",COUNTIF(AQ42:BT42,"A")) | BY42: =SUM(BV42:BX42) -> 0
A43: 34 | B43: SANDRIYA EKA ANDANI | C43: L | AH43: =IF(COUNTIF(D43:AG43,".")=0,"",COUNTIF(D43:AG43,".")) | AI43: =IF(COUNTIF(D43:AG43,"S")=0,"",COUNTIF(D43:AG43,"S")) | AJ43: =IF(COUNTIF(D43:AG43,"I")=0,"",COUNTIF(D43:AG43,"I")) | AK43: =IF(COUNTIF(D43:AG43,"A")=0,"",COUNTIF(D43:AG43,"A")) | AL43: =SUM(AI43:AK43) -> 0 | AN43: 33 | AO43: NAJLA DWI MUSTIKA | AP43: P | AQ43: . | BB43: . | BC43: . | BK43: . | BL43: . | BU43: =IF(COUNTIF(AQ43:BT43,".")=0,"",COUNTIF(AQ43:BT43,".")) -> 5 | BV43: =IF(COUNTIF(AQ43:BT43,"S")=0,"",COUNTIF(AQ43:BT43,"S")) | BW43: =IF(COUNTIF(AQ43:BT43,"I")=0,"",COUNTIF(AQ43:BT43,"I")) | BX43: =IF(COUNTIF(AQ43:BT43,"A")=0,"",COUNTIF(AQ43:BT43,"A")) | BY43: =SUM(BV43:BX43) -> 0
...

Sheet Nilai 10-5
A1: FORM NILAI PESERTA DIDIK
A2: =CV!A3 -> SMA NEGERI 15 KOTA BANDUNG
A3: =CV!A4 -> TAHUN AJARAN 2026/2027
B5: Kelas | C5: ='Absensi 10-5'!AP6 -> 10-5 | V5: Nilai Kriteria Ketuntasan Minimal (KKM)
B6: Mata Pelajaran | C6: =PROPER(CV!A27) -> Informatika | V6: 78
B7: Semester | C7: Ganjil
A9: No | B9: Nama | C9: JK | D9: Nilai Harian | S9: ASAS | T9: R2 | V9: KD / Materi Pengetahuan :
D10: PH 1 | E10: PH 2 | F10: PH 3 | G10: PH 4 | H10: PH 5 | I10: PH 6 | J10: PH 7 | K10: PH 8 | L10: PH 9 | M10: PH 10 | N10: PH 11 | O10: PH 12 | P10: PH 13 | Q10: PH 14 | R10: PH 15
D11: =IF(COUNTA(D12:D59)>0,1,0) -> 1 | E11: =IF(COUNTA(E12:E59)>0,1,0) -> 0 | F11: =IF(COUNTA(F12:F59)>0,1,0) -> 0 | G11: =IF(COUNTA(G12:G59)>0,1,0) -> 0 | H11: =IF(COUNTA(H12:H59)>0,1,0) -> 0 | I11: =IF(COUNTA(I12:I59)>0,1,0) -> 0 | J11: =IF(COUNTA(J12:J59)>0,1,0) -> 0 | K11: =IF(COUNTA(K12:K59)>0,1,0) -> 0 | ... R11: =IF(COUNTA(R12:R59)>0,1,0) -> 0 | S11: =IF(SUM(S12:S59)=0,0,1) -> 0 | T11: =SUM(D11:R11) -> 1
A12: 1 | B12: ='Absensi 10-5'!AO11 -> ADINDA PRABANDARI KINASIH | C12: ='Absensi 10-5'!AP11 -> P | D12: 58.615385 | T12: =IFERROR(IF(S$11=0,SUM(D12:R12)/T$11,SUM(D12:R12)/T$11*70%+S12*30%),"") -> 58.615385 | V12: PH 1 | W12: PTS
A13: 2 | B13: ='Absensi 10-5'!AO12 -> ALIFA MEYLANI SAFITRI | C13: ='Absensi 10-5'!AP12 -> P | D13: 54.307692 | T13: =IFERROR(IF(S$11=0,ROUNDUP(SUM(D13:R13)/T$11,0),ROUNDUP(SUM(D13:R13)/T$11*70%+S13*30%,0)),"") -> 55
A14: 3 | B14: ='Absensi 10-5'!AO13 -> AMALIA NURFADILAH | C14: ='Absensi 10-5'!AP13 -> P | D14: 62.923077 | T14: =IFERROR(IF(S$11=0,ROUNDUP(SUM(D14:R14)/T$11,0),ROUNDUP(SUM(D14:R14)/T$11*70%+S14*30%,0)),"") -> 63
A15: 4 | B15: ='Absensi 10-5'!AO14 -> ARIA KUSUMAH | C15: ='Absensi 10-5'!AP14 -> L | D15: 67.230769 | T15: =IFERROR(IF(S$11=0,ROUNDUP(SUM(D15:R15)/T$11,0),ROUNDUP(SUM(D15:R15)/T$11*70%+S15*30%,0)),"") -> 68 | V15: PH 2
A16: 5 | B16: ='Absensi 10-5'!AO15 -> AULIA KINASIH | C16: ='Absensi 10-5'!AP15 -> P | D16: 65.076923 | T16: =IFERROR(IF(S$11=0,ROUNDUP(SUM(D16:R16)/T$11,0),ROUNDUP(SUM(D16:R16)/T$11*70%+S16*30%,0)),"") -> 66
A17: 6 | B17: ='Absensi 10-5'!AO16 -> BALQIS FANIDA SORAYA | C17: ='Absensi 10-5'!AP16 -> P | D17: 54.307692 | T17: =IFERROR(IF(S$11=0,ROUNDUP(SUM(D17:R17)/T$11,0),ROUNDUP(SUM(D17:R17)/T$11*70%+S17*30%,0)),"") -> 55
A18: 7 | B18: ='Absensi 10-5'!AO17 -> CAHYA ISMAIL | C18: ='Absensi 10-5'!AP17 -> L | D18: 50 | T18: =IFERROR(IF(S$11=0,ROUNDUP(SUM(D18:R18)/T$11,0),ROUNDUP(SUM(D18:R18)/T$11*70%+S18*30%,0)),"") -> 50 | V18: PH 3
A19: 8 | B19: ='Absensi 10-5'!AO18 -> CHIARA HASNA ZHAFIRA | C19: ='Absensi 10-5'!AP18 -> P | D19: 65.076923 | T19: =IFERROR(IF(S$11=0,ROUNDUP(SUM(D19:R19)/T$11,0),ROUNDUP(SUM(D19:R19)/T$11*70%+S19*30%,0)),"") -> 66
A20: 9 | B20: ='Absensi 10-5'!AO19 -> DEVILIA AULIA PUTRI | C20: ='Absensi 10-5'!AP19 -> P | D20: 65.076923 | T20: =IFERROR(IF(S$11=0,ROUNDUP(SUM(D20:R20)/T$11,0),ROUNDUP(SUM(D20:R20)/T$11*70%+S20*30%,0)),"") -> 66
A21: 10 | B21: ='Absensi 10-5'!AO20 -> EGA YUDA NUGRAHA | C21: ='Absensi 10-5'!AP20 -> L | D21: 67.230769 | T21: =IFERROR(IF(S$11=0,ROUNDUP(SUM(D21:R21)/T$11,0),ROUNDUP(SUM(D21:R21)/T$11*70%+S21*30%,0)),"") -> 68 | V21: PH 4
A22: 11 | B22: ='Absensi 10-5'!AO21 -> ELMIRA ZAHIYA RUSDI | C22: ='Absensi 10-5'!AP21 -> P | D22: 62.923077 | T22: =IFERROR(IF(S$11=0,ROUNDUP(SUM(D22:R22)/T$11,0),ROUNDUP(SUM(D22:R22)/T$11*70%+S22*30%,0)),"") -> 63
A23: 12 | B23: ='Absensi 10-5'!AO22 -> FAHRAN FATUROHMAN | C23: ='Absensi 10-5'!AP22 -> L | D23: 62.923077 | T23: =IFERROR(IF(S$11=0,ROUNDUP(SUM(D23:R23)/T$11,0),ROUNDUP(SUM(D23:R23)/T$11*70%+S23*30%,0)),"") -> 63
A24: 13 | B24: ='Absensi 10-5'!AO23 -> FAKHIRA SALWA NABILA | C24: ='Absensi 10-5'!AP23 -> P | D24: 65.076923 | T24: =IFERROR(IF(S$11=0,ROUNDUP(SUM(D24:R24)/T$11,0),ROUNDUP(SUM(D24:R24)/T$11*70%+S24*30%,0)),"") -> 66 | V24: PH 5
A25: 14 | B25: ='Absensi 10-5'!AO24 -> FATHIYYA AMEERA QUEENNARRA EDWARD | C25: ='Absensi 10-5'!AP24 -> P | D25: 71.538462 | T25: =IFERROR(IF(S$11=0,ROUNDUP(SUM(D25:R25)/T$11,0),ROUNDUP(SUM(D25:R25)/T$11*70%+S25*30%,0)),"") -> 72
A26: 15 | B26: ='Absensi 10-5'!AO25 -> FAUZAN SYAWAL PRATAMA | C26: ='Absensi 10-5'!AP25 -> L | D26: 65.076923 | T26: =IFERROR(IF(S$11=0,ROUNDUP(SUM(D26:R26)/T$11,0),ROUNDUP(SUM(D26:R26)/T$11*70%+S26*30%,0)),"") -> 66
A27: 16 | B27: ='Absensi 10-5'!AO26 -> GHEA RAHMAYANI | C27: ='Absensi 10-5'!AP26 -> P | D27: 62.923077 | T27: =IFERROR(IF(S$11=0,ROUNDUP(SUM(D27:R27)/T$11,0),ROUNDUP(SUM(D27:R27)/T$11*70%+S27*30%,0)),"") -> 63 | V27: PH 6
A28: 17 | B28: ='Absensi 10-5'!AO27 -> INTANIA RAMADANIA | C28: ='Absensi 10-5'!AP27 -> P | D28: 52.153846 | T28: =IFERROR(IF(S$11=0,ROUNDUP(SUM(D28:R28)/T$11,0),ROUNDUP(SUM(D28:R28)/T$11*70%+S28*30%,0)),"") -> 53
A29: 18 | B29: ='Absensi 10-5'!AO28 -> JAUZA HANA NABILA | C29: ='Absensi 10-5'!AP28 -> P | D29: 54.307692 | T29: =IFERROR(IF(S$11=0,ROUNDUP(SUM(D29:R29)/T$11,0),ROUNDUP(SUM(D29:R29)/T$11*70%+S29*30%,0)),"") -> 55
A30: 19 | B30: ='Absensi 10-5'!AO29 -> KEYSHA NUR RAHAYU | C30: ='Absensi 10-5'!AP29 -> P | D30: 67.230769 | T30: =IFERROR(IF(S$11=0,ROUNDUP(SUM(D30:R30)/T$11,0),ROUNDUP(SUM(D30:R30)/T$11*70%+S30*30%,0)),"") -> 68 | V30: PH 7
A31: 20 | B31: ='Absensi 10-5'!AO30 -> MAHESYA LILY | C31: ='Absensi 10-5'!AP30 -> P | D31: 67.230769 | T31: =IFERROR(IF(S$11=0,ROUNDUP(SUM(D31:R31)/T$11,0),ROUNDUP(SUM(D31:R31)/T$11*70%+S31*30%,0)),"") -> 68
A32: 21 | B32: ='Absensi 10-5'!AO31 -> MALVIN AKSATRYA DANISWARA KUSMANA | C32: ='Absensi 10-5'!AP31 -> L | D32: 78 | T32: =IFERROR(IF(S$11=0,ROUNDUP(SUM(D32:R32)/T$11,0),ROUNDUP(SUM(D32:R32)/T$11*70%+S32*30%,0)),"") -> 78 | V32: PH 8
A33: 22 | B33: ='Absensi 10-5'!AO32 -> MARWA NURHAA NAFIAH | C33: ='Absensi 10-5'!AP32 -> P | D33: 65.076923 | T33: =IFERROR(IF(S$11=0,ROUNDUP(SUM(D33:R33)/T$11,0),ROUNDUP(SUM(D33:R33)/T$11*70%+S33*30%,0)),"") -> 66
A34: 23 | B34: ='Absensi 10-5'!AO33 -> MIKAIL AL KAUTSAR SIMA PAWITRA | C34: ='Absensi 10-5'!AP33 -> L | D34: 65.076923 | T34: =IFERROR(IF(S$11=0,ROUNDUP(SUM(D34:R34)/T$11,0),ROUNDUP(SUM(D34:R34)/T$11*70%+S34*30%,0)),"") -> 66
A35: 24 | B35: ='Absensi 10-5'!AO34 -> MUHAMAD AGUNG RIVA RISQULOH | C35: ='Absensi 10-5'!AP34 -> L | D35: 58.615385 | T35: =IFERROR(IF(S$11=0,ROUNDUP(SUM(D35:R35)/T$11,0),ROUNDUP(SUM(D35:R35)/T$11*70%+S35*30%,0)),"") -> 59 | V35: PH 9
A36: 25 | B36: ='Absensi 10-5'!AO35 -> MUHAMAD FAJAR DWI PUTRA | C36: ='Absensi 10-5'!AP35 -> L | D36: 71.538462 | T36: =IFERROR(IF(S$11=0,ROUNDUP(SUM(D36:R36)/T$11,0),ROUNDUP(SUM(D36:R36)/T$11*70%+S36*30%,0)),"") -> 72
A37: 26 | B37: ='Absensi 10-5'!AO36 -> MUHAMAD PAHMI PUTRA SANGGARA | C37: ='Absensi 10-5'!AP36 -> L | D37: 52.153846 | T37: =IFERROR(IF(S$11=0,ROUNDUP(SUM(D37:R37)/T$11,0),ROUNDUP(SUM(D37:R37)/T$11*70%+S37*30%,0)),"") -> 53
A38: 27 | B38: ='Absensi 10-5'!AO37 -> MUHAMMAD AZRIL ILHAM | C38: ='Absensi 10-5'!AP37 -> L | D38: 52.153846 | T38: =IFERROR(IF(S$11=0,ROUNDUP(SUM(D38:R38)/T$11,0),ROUNDUP(SUM(D38:R38)/T$11*70%+S38*30%,0)),"") -> 53 | V38: PH 10
A39: 28 | B39: ='Absensi 10-5'!AO38 -> MUHAMMAD KAFI AL-FATIH | C39: ='Absensi 10-5'!AP38 -> L | D39: 69.384615 | T39: =IFERROR(IF(S$11=0,ROUNDUP(SUM(D39:R39)/T$11,0),ROUNDUP(SUM(D39:R39)/T$11*70%+S39*30%,0)),"") -> 70
A40: 29 | B40: ='Absensi 10-5'!AO39 -> MUHAMMAD KARIZA AL FAKHRI | C40: ='Absensi 10-5'!AP39 -> L | D40: 67.230769 | T40: =IFERROR(IF(S$11=0,ROUNDUP(SUM(D40:R40)/T$11,0),ROUNDUP(SUM(D40:R40)/T$11*70%+S40*30%,0)),"") -> 68
A41: 30 | B41: ='Absensi 10-5'!AO40 -> MUHAMMAD MAHIN | C41: ='Absensi 10-5'!AP40 -> L | D41: 67.230769 | T41: =IFERROR(IF(S$11=0,ROUNDUP(SUM(D41:R41)/T$11,0),ROUNDUP(SUM(D41:R41)/T$11*70%+S41*30%,0)),"") -> 68 | V41: PH 11
A42: 31 | B42: ='Absensi 10-5'!AO41 -> MUHAMMAD WILDAN FIRDAUS | C42: ='Absensi 10-5'!AP41 -> L | D42: 60.769231 | T42: =IFERROR(IF(S$11=0,ROUNDUP(SUM(D42:R42)/T$11,0),ROUNDUP(SUM(D42:R42)/T$11*70%+S42*30%,0)),"") -> 61
...

Sheet PTS
C1: correct | D1: 25*4 | E1: min 3 a 35 max 16 a 65
A2: 1 | B2: ADINDA PRABANDARI KINASIH | C2: 7 | D2: =C2*4 -> 28 | E2: =50+(C2-3)*(78-50)/(16-3) -> 58.615385
A3: 2 | B3: ALIFA MEYLANI SAFITRI | C3: 5 | D3: =C3*4 -> 20 | E3: =50+(C3-3)*(78-50)/(16-3) -> 54.307692
A4: 3 | B4: AMALIA NURFADILAH | C4: 9 | D4: =C4*4 -> 36 | E4: =50+(C4-3)*(78-50)/(16-3) -> 62.923077
A5: 4 | B5: ARIA KUSUMAH | C5: 11 | D5: =C5*4 -> 44 | E5: =50+(C5-3)*(78-50)/(16-3) -> 67.230769
A6: 5 | B6: AULIA KINASIH | C6: 10 | D6: =C6*4 -> 40 | E6: =50+(C6-3)*(78-50)/(16-3) -> 65.076923
A7: 6 | B7: BALQIS FANIDA SORAYA | C7: 5 | D7: =C7*4 -> 20 | E7: =50+(C7-3)*(78-50)/(16-3) -> 54.307692
A8: 7 | B8: CAHYA ISMAIL | C8: 3 | D8: =C8*4 -> 12 | E8: =50+(C8-3)*(78-50)/(16-3) -> 50
A9: 8 | B9: CHIARA HASNA ZHAFIRA | C9: 10 | D9: =C9*4 -> 40 | E9: =50+(C9-3)*(78-50)/(16-3) -> 65.076923
A10: 9 | B10: DEVILIA AULIA PUTRI | C10: 10 | D10: =C10*4 -> 40 | E10: =50+(C10-3)*(78-50)/(16-3) -> 65.076923
A11: 10 | B11: EGA YUDA NUGRAHA | C11: 11 | D11: =C11*4 -> 44 | E11: =50+(C11-3)*(78-50)/(16-3) -> 67.230769
A12: 11 | B12: ELMIRA ZAHIYA RUSDI | C12: 9 | D12: =C12*4 -> 36 | E12: =50+(C12-3)*(78-50)/(16-3) -> 62.923077
A13: 12 | B13: FAHRAN FATUROHMAN | C13: 9 | D13: =C13*4 -> 36 | E13: =50+(C13-3)*(78-50)/(16-3) -> 62.923077
... A47: 46 | B47: ZAHIRA NAFISSA | C47: 11 | D47: =C47*4 -> 44 | E47: =50+(C47-3)*(78-50)/(16-3) -> 67.230769

Sheet DSS
A2: ANALISIS DAYA SERAP SISWA
A3: =#REF! -> #REF!
A4: =#REF! -> #REF!
A5: =#REF! -> #REF!
B7: MATA PELAJARAN | D7: =#REF! -> #REF!
B8: KELAS | D8: =#REF! -> #REF!
B9: SEMESTER | C9: =UPPER(#REF!) -> #REF! | D9: =#REF! -> #REF!
B10: JUMLAH SISWA | D10: =#REF! -> #REF!
A12: No | B12: Kompetensi Inti/ Kompetensi Dasar | E12: Tatap Muka Pembelajaran | H12: Pencapaian Target Kurikulum | K12: Daya Serap Siswa | M12: Ketuntasan Hasil Pembelajaran | Q12: Evaluasi KBM
H13: Jumlah KD | J13: % Target Kurikulum | K13: Nilai Harian Rata-rata / KD | L13: Prosentase Daya Serap Siswa / KD | M13: Ketuntasan/KD | O13: Ketuntasan Kelas
E14: Perencanaan | F14: Realisasi | G14: % TM Mengajar | H14: Dalam Silabus | I14: Realisasi | M14: Jml Siswa Remidiasi / KD | N14: % Ketuntasan / KD | O14: Rata-rata Jml Siswa Belum Tuntas tiap KD | P14: % Ketuntasan Kelas | Q14: Alasan (jika ketuntasan < 100%) | R14: Tindakan (jika ketuntasan < 100%)
A15: =IF('Program Semester'!A12="","",'Program Semester'!A12) | B15: =IF('Program Semester'!B12="","",'Program Semester'!B12) | E15: =IF('Program Semester'!C12="","",'Program Semester'!C12) | G15: =IF(ISERROR(F15/E15),"",(F15/E15)) | H15: =IF(COUNTA($A$15:$A$28)-COUNTIF($A$15:$A$28,"")=0,"",COUNTA($A$15:$A$28)-COUNTIF($A$15:$A$28,"")) | I15: =IF(H15="","",H15) | J15: =IFERROR(H15/I15,"") | K15: =IFERROR(AVERAGE('Nilai 10-5'!D12:D59),"") -> 63.016722 | L15: =IFERROR(K15/100,"") -> 0.63016722 | N15: =IF(A15="","",($D$10-M15)/$D$10) | O15: =IFERROR((SUM($M$15:$M$28))/$A$29,"") | P15: =IFERROR((($D$10-O15)/$D$10),"")
A16: =IF('Program Semester'!A13="","",'Program Semester'!A13) | B16: =IF('Program Semester'!B13="","",'Program Semester'!B13) | E16: =IF('Program Semester'!C13="","",'Program Semester'!C13) | G16: =IF(ISERROR(F16/E16),"",(F16/E16)) | K16: =IFERROR(AVERAGE('Nilai 10-5'!K12:K59),"") | L16: =IFERROR(K16/100,"") | N16: =IF(A16="","",($D$10-M16)/$D$10)
